Workbook

Sheet Trang Bìa
A3: HỌC VIỆN CÔNG NGHỆ BƯU CHÍNH VIỄN THÔNG
A4: KHOA CÔNG NGHỆ THÔNG TIN I
A11: BÁO CÁO
A12: BÀI TẬP DỰ ÁN NHÓM
A13: MÔN ĐẢM BẢO CHẤT LƯỢNG PHẦN MỀM
C15: Giảng viên hướng dẫn:
C16: Nhóm bài tập:
C17: Nhóm học phần:
C18: Chủ đề: | E18: Hệ thống thương mại điện tử TechStore theo kiến trúc microservices tích hợp trí tuệ nhân tạo
C21: Thành viên của nhóm:
B23: Tên | D23: MSV | F23: Chức năng / Nhiệm vụ | K23: Đóng góp
F24: Lập Kế hoạch kiểm thử; Module PH1 – Tài khoản, xác thực & phân quyền; PH2 – Sản phẩm & tìm kiếm
F25: Checklist Review kế hoạch test; Module PH3 – Giỏ hàng & đơn hàng; PH4 – Tồn kho
F26: Checklist Review tài liệu hướng dẫn cài đặt; Module PH5 – Thanh toán; PH6 – Khuyến mãi & chiến dịch
F27: Checklist Review tài liệu thiết kế; Module PH7 – Thông báo; PH8 – Hành vi & gợi ý
F28: Checklist Review SRS; Module PH9 – Phân tích AI & churn; PH10 – Chatbot & chat
B35: Hà Nội, tháng 10 năm 2026

Sheet Phân công công việc
A1: Mã nguồn (Code + Document) | B1: A:\Graduation-Project (nhánh develop)
A2: Tài liệu kiểm thử | B2: A:\Graduation-Project\docs\test (TEST_CASES_TOAN_HE_THONG.xlsx, HUONG_DAN_TEST_THU_CONG.md)
A3: Báo cáo đồ án (SRS / thiết kế) | B3: A:\Do_An_Tot_Nghiep\bao-cao\bao-cao (CHUONG_I, CHUONG_II, CHUONG_III)
A4: Phân công công việc chung
A5: Nội dung | B5: Thành viên | C5: Chú thích
A6: Tạo kế hoạch test (Plan Test) | C6: Sheet 'Phần_1-Kế hoạch kiểm thử'
A7: Checklist Review kế hoạch test (Plan test) | C7: Theo mẫu của bộ môn
A8: Checklist Review tài liệu đặc tả (SRS) | C8: SRS = Chương I, II báo cáo + docs/services
A9: Checklist Review tài liệu thiết kế | C9: Chương III báo cáo + docs/services
A10: Checklist Review tài liệu hướng dẫn cài đặt | C10: README.md, BE/README.md, BE/DEPLOY.md, AI/README.md
A12: Công việc làm từng cá nhân
A13: Chức năng / Nhóm chức năng | B13: Thành viên | C13: Chú thích
A14: PH1 – Tài khoản, xác thực & phân quyền
A15: PH2 – Sản phẩm, danh mục, đánh giá & tìm kiếm
A16: PH3 – Giỏ hàng & đơn hàng
A17: PH4 – Tồn kho
A18: PH5 – Thanh toán
A19: PH6 – Khuyến mãi, chiến dịch, voucher & điểm thưởng
A20: PH7 – Thông báo
A21: PH8 – Hành vi người dùng & gợi ý sản phẩm
A22: PH9 – Phân tích AI & dự đoán khách rời bỏ
A23: PH10 – Chatbot AI & chat với nhân viên

Sheet Mục Lục
A1: MỤC LỤC
A2: Mã nguồn dự án sẽ tiến hành đảm bảo chất lượng | I2: A:\Graduation-Project
A4: I | B4: Công việc chung của nhóm | I4: =HYPERLINK("#'Phần_1-Công việc chung'!A1","click here") -> click here
A5: 1 | B5: Mô tả hệ thống | I5: =HYPERLINK("#'Phần_1-Công việc chung'!A1","click here") -> click here
A6: 2 | B6: Tài liệu bổ sung và Review tài liệu chung
A7: 2.1 | B7: Bản kế hoạch kiểm thử | I7: =HYPERLINK("#'Phần_1-Kế hoạch kiểm thử'!A1","click here") -> click here
A8: 2.2 | B8: Review kế hoạch kiểm thử | I8: =HYPERLINK("#'Phần_1-Review kế hoạch test'!A1","click here") -> click here
A9: 2.3 | B9: SRS Review Checklist | I9: =HYPERLINK("#'Phần_1-SRS Review Checklist'!A1","click here") -> click here
A10: 2.4 | B10: Review tài liệu thiết kế | I10: =HYPERLINK("#'Phần_1-Review TL thiết kế'!A1","click here") -> click here
A11: 2.5 | B11: Review tài liệu hướng dẫn cài đặt | I11: =HYPERLINK("#'Phần_1-Review TL HD cài đặt'!A1","click here") -> click here
A13: II | B13: Công việc cá nhân
A14: 1 | C14: PH1 – Tài khoản, xác thực & phân quyền
A15: 1.1 | C15: SRS Review Checklist | I15: =HYPERLINK("#'PH1-Review SRS'!A1","click here") -> click here
A16: 1.2 | C16: Review Code | I16: =HYPERLINK("#'PH1-Review Code'!A1","click here") -> click here
A17: 1.3 | C17: Kiểm thử giao diện | I17: =HYPERLINK("#'PH1-Kiểm thử giao diện'!A1","click here") -> click here
A18: 1.4 | C18: Unit Testing | I18: =HYPERLINK("#'PH1-Unit test'!A1","click here") -> click here
A19: 1.5 | C19: Kiểm thử API | I19: =HYPERLINK("#'PH1-Kiểm thử API(Postman)'!A1","click here") -> click here
A20: 1.6 | C20: Kiểm thử tự động | I20: =HYPERLINK("#'PH1-Kiểm thử tự động'!A1","click here") -> click here
A21: 1.7 | C21: Kiểm thử hiệu năng | I21: =HYPERLINK("#'PH1-Kiểm thử hiệu năng'!A1","click here") -> click here
A22: 1.8 | C22: Đánh giá kết quả | I22: =HYPERLINK("#'PH1-Đánh giá kết quả'!A1","click here") -> click here
A23: 2 | C23: PH2 – Sản phẩm, danh mục, đánh giá & tìm kiếm
A24: 2.1 | C24: SRS Review Checklist | I24: =HYPERLINK("#'PH2-Review SRS'!A1","click here") -> click here
A25: 2.2 | C25: Review Code | I25: =HYPERLINK("#'PH2-Review Code'!A1","click here") -> click here
A26: 2.3 | C26: Kiểm thử giao diện | I26: =HYPERLINK("#'PH2-Kiểm thử giao diện'!A1","click here") -> click here
A27: 2.4 | C27: Unit Testing | I27: =HYPERLINK("#'PH2-Unit test'!A1","click here") -> click here
A28: 2.5 | C28: Kiểm thử API | I28: =HYPERLINK("#'PH2-Kiểm thử API(Postman)'!A1","click here") -> click here
A29: 2.6 | C29: Kiểm thử tự động | I29: =HYPERLINK("#'PH2-Kiểm thử tự động'!A1","click here") -> click here
A30: 2.7 | C30: Kiểm thử hiệu năng | I30: =HYPERLINK("#'PH2-Kiểm thử hiệu năng'!A1","click here") -> click here
A31: 2.8 | C31: Đánh giá kết quả | I31: =HYPERLINK("#'PH2-Đánh giá kết quả'!A1","click here") -> click here
A32: 3 | C32: PH3 – Giỏ hàng & đơn hàng
A33: 3.1 | C33: SRS Review Checklist | I33: =HYPERLINK("#'PH3-Review SRS'!A1","click here") -> click here
A34: 3.2 | C34: Review Code | I34: =HYPERLINK("#'PH3-Review Code'!A1","click here") -> click here
A35: 3.3 | C35: Kiểm thử giao diện | I35: =HYPERLINK("#'PH3-Kiểm thử giao diện'!A1","click here") -> click here
A36: 3.4 | C36: Unit Testing | I36: =HYPERLINK("#'PH3-Unit test'!A1","click here") -> click here
A37: 3.5 | C37: Kiểm thử API | I37: =HYPERLINK("#'PH3-Kiểm thử API(Postman)'!A1","click here") -> click here
A38: 3.6 | C38: Kiểm thử tự động | I38: =HYPERLINK("#'PH3-Kiểm thử tự động'!A1","click here") -> click here
A39: 3.7 | C39: Kiểm thử hiệu năng | I39: =HYPERLINK("#'PH3-Kiểm thử hiệu năng'!A1","click here") -> click here
A40: 3.8 | C40: Đánh giá kết quả | I40: =HYPERLINK("#'PH3-Đánh giá kết quả'!A1","click here") -> click here
A41: 4 | C41: PH4 – Tồn kho
A42: 4.1 | C42: SRS Review Checklist | I42: =HYPERLINK("#'PH4-Review SRS'!A1","click here") -> click here
...

Sheet Phần_1-Công việc chung
A2: I. CÔNG VIỆC CHUNG CỦA NHÓM
B3: 1. Mô tả hệ thống
B4: 1.1. Giới thiệu về hệ thống
C5: TechStore (AuraTech) là hệ thống thương mại điện tử bán thiết bị công nghệ, xây dựng theo kiến trúc microservices, tích hợp các dịch vụ AI: tìm kiếm ngữ nghĩa & bằng hình ảnh, gợi ý sản phẩm, dự đoán khách rời bỏ và chatbot tư vấn.
B6: 1.2. Công nghệ sử dụng
C7: - | D7: Frontend: React 19 + Vite 7 + Tailwind CSS; đăng nhập bằng keycloak-js (OIDC + PKCE).
C8: - | D8: Backend: 8 microservice Spring Boot 3.2.5 (Java 17) – user, product, order, inventory, payment, promotion, notification, chat; Spring Cloud Gateway, Eureka; gRPC giữa order ↔ product/inventory.
C9: - | D9: Giao tiếp bất đồng bộ: Kafka 7.4 (KRaft) + Debezium 2.5 CDC theo mẫu Transactional Outbox; Saga bù trừ cho đơn hàng.
C10: - | D10: AI Services (Python FastAPI): search (multilingual-e5-large + CLIP ViT-B/32 + FAISS + Elasticsearch BM25), recs (SASRec), forecast (KMeans, Logistic Regression), chatbot (DeepSeek + RAG).
C11: - | D11: Cơ sở dữ liệu: MariaDB 10.11 (mỗi service 1 database), MongoDB 6 (chat, thông báo), Redis 7 (cache, giỏ hàng, giữ tồn kho), Elasticsearch 8.10.2, MinIO (ảnh).
C12: - | D12: Bảo mật: Keycloak 24 (OAuth2/OIDC), phân quyền ROLE_ADMIN / ROLE_STAFF / ROLE_CUSTOMER; Camunda BPMN cho chiến dịch khuyến mãi.
B13: 1.3. Chức năng chính của hệ thống
D14: - PH1 – Tài khoản, xác thực & phân quyền:
D15: + | E15: Đăng ký/đăng nhập qua Keycloak, hồ sơ, địa chỉ, hạng thành viên; quản trị người dùng, khóa, đổi hạng, phân quyền.
D16: - PH2 – Sản phẩm, danh mục, đánh giá & tìm kiếm:
D17: + | E17: Danh mục, thương hiệu, sản phẩm & biến thể, đánh giá, yêu thích; tìm kiếm từ khóa, ngữ nghĩa, bằng hình ảnh.
D18: - PH3 – Giỏ hàng & đơn hàng:
D19: + | E19: Giỏ hàng, checkout (VAT 10%, phí ship 30.000đ), Saga đơn hàng, hủy đơn, vận chuyển (webhook), bảo hành.
D20: - PH4 – Tồn kho:
D21: + | E21: Tồn kho theo biến thể, nhập kho, lịch sử giao dịch DEDUCT/RELEASE/RESTOCK, đồng bộ Redis.
D22: - PH5 – Thanh toán:
D23: + | E23: Thanh toán COD, VNPay sandbox (IPN có chữ ký), hoàn tiền tự động và thủ công.
D24: - PH6 – Khuyến mãi, chiến dịch, voucher & điểm thưởng:
D25: + | E25: Trình dựng chiến dịch kéo-thả → BPMN/Camunda; voucher %, giảm tiền, freeship; điểm thưởng.
D26: - PH7 – Thông báo:
D27: + | E27: Thông báo email theo sự kiện đơn hàng/thanh toán qua Kafka.
D28: - PH8 – Hành vi người dùng & gợi ý sản phẩm:
D29: + | E29: Thu thập hành vi (19 loại sự kiện), gợi ý cá nhân hóa SASRec → Recency → Popularity.
D30: - PH9 – Phân tích AI & dự đoán khách rời bỏ:
D31: + | E31: Phân khúc khách hàng, dự đoán rời bỏ, quét rủi ro phát voucher giữ chân; dashboard AI.
D32: - PH10 – Chatbot AI & chat với nhân viên:
D33: + | E33: Chatbot AI (chính sách, sản phẩm, đơn hàng), chuyển sang nhân viên, chat thời gian thực qua WebSocket.
B34: 1.4 Hiện trạng đảm bảo chất lượng của hệ thống
C35: 1. Thời điểm khi mới nhận phần mềm:
C36: - | D36: Phần mềm có mã nguồn đầy đủ (nhánh develop) và tài liệu kỹ thuật theo từng service (docs/services).
C37: - | D37: Đặc tả và thiết kế nằm trong báo cáo đồ án (Chương I–III) nhưng có nhiều điểm lệch so với code (xem RA_SOAT_BAO_CAO_VS_CODE.md).
C38: - | D38: Có tài liệu hướng dẫn cài đặt (README, BE/DEPLOY.md) và hướng dẫn test thủ công.
C39: - | D39: Gần như chưa có kiểm thử tự động: 3 file unit test Java, 9 file pytest; FE không có test.
C40: - | D40: Chưa có kế hoạch kiểm thử, bộ ca kiểm thử API/UI tự động và đo hiệu năng.
C41: 2. Hiện trạng đảm bảo chất lượng tại thời điểm báo cáo
...

Sheet Phần_1-Kế hoạch kiểm thử
A1: KẾ HOẠCH KIỂM THỬ HỆ THỐNG THƯƠNG MẠI ĐIỆN TỬ TECHSTORE
A3: Mục | B3: Nội dung
A4: Tên tài liệu | B4: Kế hoạch kiểm thử (Test Plan)
A5: Mã dự án | B5: TECHSTORE_2026
A6: Mã hiệu tài liệu | B6: TS-TP-01
A7: Phiên bản | B7: v1.0
A8: Ngày ban hành | B8: 17/10/2026
A9: Đơn vị | B9: Học viện Công nghệ Bưu chính Viễn thông – Khoa CNTT1
A10: Người lập | B10: (để trống)
A11: Người xem xét | B11: (để trống)
A12: Người phê duyệt | B12: (để trống)
A14: Đầu trang: "Kế hoạch kiểm thử TechStore – v1.0". Chân trang: "TS-TP-01 – Trang x/y".
A15: Bảng ghi nhận thay đổi
A16: Phiên bản | B16: Ngày | C16: Nội dung thay đổi | D16: Người thực hiện
A17: v1.0 | B17: 17/10/2026 | C17: Tạo mới | D17: (để trống)
A19: Tài liệu liên quan
A20: Tên tài liệu | B20: Ngày | C20: Nguồn
A21: Đặc tả hệ thống (Chương I – Đặc tả) | B21: 11/10/2026 | C21: A:\Do_An_Tot_Nghiep\bao-cao\bao-cao\CHUONG_I_DAC_TA.md
A22: Pha phân tích (Chương II) | B22: 13/10/2026 | C22: CHUONG_II_PHA_PHAN_TICH.md
A23: Pha thiết kế (Chương III) | B23: 15/10/2026 | C23: CHUONG_III_PHA_THIET_KE.md
A24: Đặc tả từng service | B24: 10/2026 | C24: docs/services/00_INDEX.md … 10_CHAT_SERVICE.md
A25: Hướng dẫn cài đặt | B25: 10/2026 | C25: README.md, BE/README.md, BE/DEPLOY.md, AI/README.md
A26: Hướng dẫn test thủ công | B26: 10/2026 | C26: docs/test/HUONG_DAN_TEST_THU_CONG.md
A28: 1. Giới thiệu
A29: 1.1 Mục đích
A30: Xác định phạm vi, chiến lược, nguồn lực, lịch trình và tiêu chí kiểm thử cho hệ thống TechStore (nhánh develop),
A31: làm căn cứ thực hiện và đánh giá kết quả kiểm thử của 10 phân hệ.
A32: 1.2 Cấu trúc tài liệu
A33: Giới thiệu → Phạm vi → Chiến lược & loại kiểm thử → Môi trường & công cụ → Tiêu chí → Rủi ro → Lịch → Nhân sự → Sản phẩm bàn giao → Ràng buộc.
A34: 1.3 Mục tiêu và phạm vi tóm tắt
A35: Phát hiện lỗi chức năng, phân quyền, toàn vẹn dữ liệu và hiệu năng trước khi bảo vệ đồ án; đo tỉ lệ đạt theo từng phân hệ.
A36: 2. Phạm vi kiểm thử
A37: 2.1 Các chức năng được kiểm thử
A38: Mã | B38: Phân hệ | C38: Thành phần
A39: PH1 | B39: Tài khoản, xác thực & phân quyền | C39: Keycloak, user-service, api-gateway
A40: PH2 | B40: Sản phẩm, danh mục, đánh giá & tìm kiếm | C40: product-service, Elasticsearch, AI search-service
A41: PH3 | B41: Giỏ hàng & đơn hàng | C41: order-service (Saga, Outbox, Debezium)
A42: PH4 | B42: Tồn kho | C42: inventory-service (Redis + MariaDB)
A43: PH5 | B43: Thanh toán | C43: payment-service (COD, VNPay sandbox, hoàn tiền)
A44: PH6 | B44: Khuyến mãi, chiến dịch, voucher & điểm | C44: promotion-service (Camunda), loyalty trong user-service
...

Sheet Phần_1-Review kế hoạch test
A1: Checklist Review Kế hoạch test
A3: Mã dự án | B3: TECHSTORE_2026
A4: Phiên bản của sản phẩm | B4: v1.0
A5: Người xem xét
A6: Ngày xem xét | B6: 17/10/2026
A7: Lần xem xét | B7: 1
A8: Độ lớn sản phẩm | B8: 10 phân hệ (PH1–PH10): 8 microservice nghiệp vụ Java + API Gateway + 4 service AI; tài liệu Test Plan 10 mục
A9: Nguồn lực dùng cho xem xét (MH) | B9: 2
A11: Câu hỏi | B11: Có | C11: Không | D11: N/A | E11: Ghi chú | F11: Điều kiện
A12: Kiểm soát tài liệu
A13: Tài liệu có tuân thủ theo yêu cầu kiểm soát tài liệu không: | C13: x | E13: Có bảng thông tin đầu tài liệu (mã dự án TECHSTORE_2026, mã hiệu TS-TP-01, v1.0, ngày 17/10/2026) nhưng tài liệu là file Markdown test_plan.md: không có header/footer thật, không đánh số trang, Người lập/Người xem xét/Người phê duyệt đều '(để trống)', chưa có chữ ký. | F13: Bắt buộc
A14: Mẫu tài liệu có phải là mẫu mới nhất không? | C14: x | E14: Không dẫn chiếu mã/phiên bản biểu mẫu Test Plan nào; bố cục tự soạn dạng Markdown theo các mục của checklist, không phải biểu mẫu Word chuẩn của đơn vị. | F14: Bắt buộc
A15: Trang tiêu đề có bao gồm đủ tên tài liệu, phiên bản và tên công ty, mã dự án, mã hiệu tài liệu và thời gian ban hành không? | B15: x | E15: Bảng đầu tài liệu có đủ: Tên tài liệu, Mã dự án TECHSTORE_2026, Mã hiệu TS-TP-01, v1.0, Ngày ban hành 17/10/2026, Đơn vị PTIT – Khoa CNTT1. Tuy nhiên đây là bảng ở đầu file, chưa tách thành trang tiêu đề riêng và không có logo. | F15: Bắt buộc
A16: Đầu và cuối trang có bao gồm tên, phiên bản của tài liệu không? | C16: x | E16: Dòng 15 chỉ mô tả ý định ('Đầu trang: Kế hoạch kiểm thử TechStore – v1.0. Chân trang: TS-TP-01 – Trang x/y'); Markdown không có header/footer thực tế. Cần thiết lập khi chuyển sang Word/PDF. | F16: Bắt buộc
A17: Đánh số trang có theo đúng quy định: số thứ tự/tổng số trang? | C17: x | E17: Chỉ có placeholder 'Trang x/y' ở dòng 15; file Markdown không phân trang nên chưa có số trang thật. | F17: Bắt buộc
A18: Trang ký có bao gồm đủ Người lập, Người xem xét & Người phê duyệt không? | C18: x | E18: Có 3 trường Người lập/Người xem xét/Người phê duyệt trong bảng đầu tài liệu nhưng đều '(để trống)', không có trang ký riêng, không có chữ ký và ngày ký. | F18: Bắt buộc
A19: Có Bảng ghi nhận thay đổi không? | B19: x | E19: Mục 'Bảng ghi nhận thay đổi': 1 dòng v1.0 – 17/10/2026 – Tạo mới; cột Người thực hiện '(để trống)'. | F19: Bắt buộc
A20: Đối với trường hợp phiên bản tài liệu > v1.0: | D20: x | E20: Tài liệu ở phiên bản v1.0, chưa có thay đổi nên không áp dụng. | F20: Bắt buộc
A21: Các nội dung ghi nhận trong Bảng ghi nhận thay đổi này có đầy đủ và đúng không? | D21: x | E21: Bản v1.0 (Tạo mới) nên không áp dụng; lưu ý cột Người thực hiện vẫn để trống. | F21: Bắt buộc
A22: Có liệt kê các tài liệu liên quan không? | B22: x | E22: Mục 'Tài liệu liên quan' liệt kê 6 tài liệu (Chương I–III, docs/services, hướng dẫn cài đặt, HUONG_DAN_TEST_THU_CONG.md). Đường dẫn không thống nhất: Chương I dùng đường dẫn tuyệt đối máy cá nhân A:\Do_An_Tot_Nghiep\..., Chương II/III chỉ có tên file; cột Ngày ghi chung '10/2026', không có phiên bản tài liệu. | F22: Bắt buộc
A23: Thông tin chung
A24: Giới thiệu chung về mục đích và cấu trúc tài liệu? | B24: x | E24: Mục 1.1 Mục đích và 1.2 Cấu trúc tài liệu. Thứ tự ở 1.2 (Tiêu chí → Rủi ro → Lịch → Nhân sự → Sản phẩm → Ràng buộc) không khớp thứ tự thực tế (5 Tiêu chí, 6 Rủi ro, 7 Ràng buộc, 8 Lịch, 9 Nhân sự, 10 Sản phẩm). | F24: Bắt buộc
A25: Tóm tắt thông tin chung: mục tiêu và phạm vi test? | B25: x | E25: Mục 1.3: phát hiện lỗi chức năng, phân quyền, toàn vẹn dữ liệu, hiệu năng; 'đo tỉ lệ đạt theo từng phân hệ' nhưng không nêu tỉ lệ mục tiêu cụ thể. | F25: Bắt buộc
A26: Kế hoạch test
A27: Trong kế hoạch, có phạm vi cụ thể về: | B27: x | E27: Mục 2 Phạm vi kiểm thử (2.1 được kiểm thử, 2.2 không kiểm thử).
A28: Việc xác định rõ sản phẩm cần test: bao gồm các chức năng/tính năng sẽ được hoặc không được test chưa? | B28: x | E28: 2.1 liệt kê 10 phân hệ PH1–PH10 kèm service; 2.2 loại trừ VNPay thật, email thật/FCM, GHTK thật, /stores, /tradein, tải quy mô production. Chưa ánh xạ phân hệ với mã use case của Chương I. | F28: Bắt buộc
A29: Các bước test: | B29: x | E29: Mục 3.1 bảng 4 mức kiểm thử với Mục đích / Cách thực hiện / Điều kiện hoàn thành. | F29: Bắt buộc
A30: Unit Testing | B30: x | E30: JUnit 5 + Mockito, pytest. Điều kiện hoàn thành '100% ca chạy; lớp *Test xanh' chỉ đo việc chạy, không đặt ngưỡng độ phủ dù đã liệt kê JaCoCo 0.8.11 ở mục 4.
A31: Integration Testing | B31: x | E31: Postman/Newman qua gateway, mô phỏng IPN VNPay và webhook vận chuyển có chữ ký; hoàn thành khi 100% ca API đã chạy.
A32: System Testing | B32: x | E32: Playwright (Chromium) black-box, mỗi phân hệ ≥ 15 ca UI, ca Fail có ảnh chụp.
A33: Acceptance testing | B33: x | E33: Checklist nghiệm thu theo use case Chương I; không xác định ai nghiệm thu (người dùng/GVHD), tiêu chí 'không còn lỗi mức Cao chưa có phương án' chưa định nghĩa thang mức độ lỗi.
A34: Có liệt kê các rủi ro ảnh hưởng đến việc thực hiện test không? | B34: x | E34: Mục 6 có 6 rủi ro (RAM, Keycloak import lại realm, email thật, AI phụ thuộc mạng, dữ liệu churn tổng hợp, rate-limit 429). Thiếu rủi ro lịch quá ngắn (2 ngày), rủi ro nhân sự, và rủi ro image Docker không tải được (thực tế minio/minio:latest không pull được phải thay pgsty/minio). | F34: Bắt buộc
A35: Nếu có, có điền đầy đủ và đúng thông tin sau: | B35: x | E35: Mỗi rủi ro đều có cột Mức độ ảnh hưởng và Phương án. | F35: Bắt buộc
A36: Phương án khắc phục và phòng ngừa | B36: x | E36: Có cột 'Phương án phòng ngừa / khắc phục' nhưng gộp chung, không tách phòng ngừa với khắc phục, không có người chịu trách nhiệm/thời điểm kích hoạt. | F36: Bắt buộc
A37: Mức độ ảnh hưởng | B37: x | E37: Có thang Cao/Trung bình/Thấp cho từng rủi ro; chưa có cột khả năng xảy ra (xác suất) nên chưa xếp hạng ưu tiên được. | F37: Bắt buộc
A38: Có liệt kê ràng buộc cho test không? | B38: x | E38: Mục 7 chỉ có 2 ràng buộc (chỉ test local; không sửa mã nguồn chính). Chưa nêu ràng buộc thời gian (17–18/10), phần cứng một laptop 24 GB, giới hạn API bên thứ ba (DeepSeek, VNPay sandbox).
A39: Các yêu cầu cho test hệ thống không? | B39: x | E39: Mục 4 (môi trường, dữ liệu, tài khoản) và mục 5 tiêu chí bắt đầu (9 service đăng ký Eureka, dữ liệu đã nạp, tài khoản đăng nhập được). Chưa nêu mật khẩu/cách tạo tài khoản test admin/staff/customer/qa_cust2. | F39: Bắt buộc
A40: Có những kiểu test nào sau đây: | B40: x | E40: Mục 3.2 bảng 6 loại kiểm thử.
A41: Function testing | B41: x | E41: 3.2: API + UI, kỳ vọng theo nghiệp vụ đúng chứ không theo hành vi hiện tại. | F41: Bắt buộc
A42: User interface testing | B42: x | E42: 3.2: Playwright, viewport 1366 và 375 px; chặn script bên thứ ba (rss2json).
...

Sheet Phần_1-SRS Review Checklist
A1: SRS Review Checklist
A3: Mã dự án | B3: TECHSTORE_2026
A4: Phiên bản sản phẩm | B4: v1.0
A5: Phân hệ / Module | B5: Toàn hệ thống
A6: Lần xem xét | B6: 1
A7: Người xem xét
A8: Ngày xem xét | B8: 17/10/2026
A9: Độ lớn sản phẩm | B9: Chương I (307 dòng: 67 thuật ngữ, 23 UC tổng quan, 8 biểu đồ UC), Chương II (1.232 dòng: 7 kịch bản chi tiết, 47 lớp thực thể), MUC_LUC (472 dòng: 10 phân hệ, 9 quy trình), docs/services 11 tệp (~5.370 dòng); 0 yêu cầu phi chức năng được đặc tả
A10: Nguồn lực dành cho xem xét (MH) | B10: 8
A12: Câu hỏi | B12: Có | C12: Không | D12: N/A | E12: Ghi chú | F12: Điều kiện
A13: Kiểm soát tài liệu
A14: Tài liệu có tuân thủ theo yêu cầu kiểm soát tài liệu không: | C14: x | E14: Bộ SRS gồm các file Markdown (CHUONG_I_DAC_TA.md, CHUONG_II_PHA_PHAN_TICH.md, MUC_LUC_BAO_CAO.md, docs/services/*.md): không có mã hiệu tài liệu, người lập/xem xét/phê duyệt, ngày ban hành. Chỉ docs/services/00_INDEX.md:15 ghi 'Phiên bản 1.0.0 | Cập nhật 2026-06-01'. | F14: Bắt buộc
A15: Mẫu tài liệu có phải là mẫu mới nhất không? | C15: x | E15: Không dùng mẫu SRS: CHUONG_I_DAC_TA.md/CHUONG_II_PHA_PHAN_TICH.md theo khung đề cương PTTKHTTT (bảng từ khóa, mô tả 5 bước, UC, kịch bản, lớp thực thể). Mỗi file docs/services có bố cục riêng (I. Tổng quan … Cấu hình Docker). MUC_LUC_BAO_CAO.md là dàn ý báo cáo, không phải SRS. | F15: Bắt buộc
A16: Trang tiêu đề có bao gồm đủ tên tài liệu, phiên bản, tên công ty và logo, mã dự án, mã hiệu tài liệu và thời gian ban hành không? | C16: x | E16: Chỉ có heading '# CHƯƠNG I: ĐẶC TẢ HỆ THỐNG' (CHUONG_I_DAC_TA.md:1) và '# CHƯƠNG II: PHA PHÂN TÍCH' (CHUONG_II_PHA_PHAN_TICH.md:1). Không có trang tiêu đề, công ty, logo, mã dự án, mã hiệu, ngày ban hành. | F16: Bắt buộc
A17: Đầu và cuối trang có bao gồm tên, phiên bản của tài liệu, Mã hiệu của template không? | C17: x | E17: File Markdown không có header/footer trang. | F17: Bắt buộc
A18: Đánh số trang có theo đúng qui định: số thứ tự/tổng số trang? | C18: x | E18: Markdown không đánh số trang. MUC_LUC mục 8 chỉ dự kiến phân bổ số trang. | F18: Bắt buộc
A19: Trang ký có bao gồm đủ Người xem xét & Người phê duyệt không? | C19: x | E19: Không có trang ký trong Chương I, Chương II, MUC_LUC hay docs/services. | F19: Bắt buộc
A20: Có bảng theo dõi lịch sử thay đổi không? | C20: x | E20: Không có bảng lịch sử thay đổi. Chỉ có các banner rà soát (docs/services/00_INDEX.md:3-11 'rà soát 2026-10-11') và dòng 'Version: 2.0.0' ở docs/services/01_IDENTITY_USER_SERVICE.md:14. Không ghi lại thay đổi giữa các phiên bản. | F20: Bắt buộc
A21: Đối với trường hợp phiên bản tài liệu > v1.0: | D21: x | E21: Bộ SRS được xem xét ở phiên bản v1.0 (đồ án). Lưu ý: 01_IDENTITY_USER_SERVICE.md ghi Version 2.0.0 nhưng không có bảng thay đổi.
A22: Các nội dung ghi nhận trong Bảng ghi nhận thay đổi này có đầy đủ và đúng không? | D22: x | E22: Không áp dụng (v1.0, không có bảng ghi nhận thay đổi). | F22: Bắt buộc
A23: Giới thiệu chung
A24: Có nêu rõ mục đích của tài liệu không? | C24: x | E24: CHUONG_I_DAC_TA.md Bước 1 (:82-83) chỉ nêu mục đích của HỆ THỐNG, không nêu mục đích của tài liệu SRS và người đọc dự kiến. MUC_LUC_BAO_CAO.md:3-10 nêu mục đích bố cục báo cáo, không phải mục đích đặc tả. | F24: Bắt buộc
A25: Phạm vi hệ thống có được mô tả rõ ràng không? | B25: x | E25: CHUONG_I_DAC_TA.md Bước 2 (:85-93) mô tả phạm vi theo 6 nhóm người dùng. Nhưng nhiều mục ngoài phạm vi code: thu cũ đổi mới, tra cứu cửa hàng, giỏ hàng của khách vãng lai, Nhân viên kho/Supplier (RA_SOAT_BAO_CAO_VS_CODE.md B1, B2, B3, A4). Trái với nguyên tắc 'MUC_LUC_BAO_CAO.md:8-10' (chưa có mã nguồn thì không đưa vào).
A26: Các khái niệm và thuật ngữ có được định nghĩa đầy đủ không? | B26: x | E26: CHUONG_I_DAC_TA.md mục 1 (:3-76): bảng 67 từ khóa chia 3 nhóm (con người, đối tượng, hoạt động). Thiếu thuật ngữ kỹ thuật dùng trong Chương II (Outbox, CDC/Debezium, Saga, IPN, JWT/OIDC, SASRec, RAG, BPMN). Có thuật ngữ cho khái niệm không tồn tại: Trade-In (#30, #63, #64), Warehouse Staff (#5) (RA_SOAT_BAO_CAO_VS_CODE.md A4, B1). | F26: Bắt buộc
A27: Có liệt kê các tài liệu tham khảo không? | C27: x | E27: Chương I/II không có danh mục tài liệu tham khảo. MUC_LUC_BAO_CAO.md:105 và :452 chỉ dự kiến mục 'Tài liệu tham khảo' theo chuẩn IEEE.
A28: Nếu có, mỗi tài liệu có bao gồm các thông tin sau không? | D28: x | E28: Không có danh mục tài liệu tham khảo.
A29: Tên tài liệu | D29: x | E29: Không có danh mục tài liệu tham khảo.
A30: Ngày phát hành | D30: x | E30: Không có danh mục tài liệu tham khảo.
A31: Nguồn | D31: x | E31: Không có danh mục tài liệu tham khảo.
A32: Có mô tả giới hạn của tài liệu không? | C32: x | E32: Chương I/II không có mục giới hạn. Chỉ MUC_LUC_BAO_CAO.md:8-10 ('Giả định phạm vi') và :318 (danh sách 'Không đưa vào báo cáo': MoMo, RMA, SMS, CI/CD, giám sát, sao lưu) có nhắc. Chính Chương I lại vi phạm giới hạn này khi đặc tả Trade-In, cửa hàng (RA_SOAT_BAO_CAO_VS_CODE.md B1-B2). | F32: Bắt buộc
A33: Có mô tả tổ chức của tài liệu không? | B33: x | E33: MUC_LUC_BAO_CAO.md mục 1 (:14-125) mô tả bố cục Mở đầu + 4 chương và cách chia Chương 3. Nhưng bố cục này không khớp các file chương hiện có (Mục lục ghi Chương 1 là 'Bài toán', UC ở 3.2) (RA_SOAT_BAO_CAO_VS_CODE.md B26). | F33: Bắt buộc
A34: Mô tả tổng thể
A35: Có xác định ngữ cảnh và điều kiện sử dụng của hệ thống (scenarios and operational concepts) không? | B35: x | E35: CHUONG_I_DAC_TA.md Bước 3 (:95-118) có 7 nghiệp vụ cốt lõi. CHUONG_II_PHA_PHAN_TICH.md mục 1.1-1.7 có 7 kịch bản chi tiết. MUC_LUC_BAO_CAO.md 2.4 (:196-212) có 9 quy trình QT1-QT9. Nhưng nhiều bước sai so với code: trừ kho sau thanh toán, trạng thái PAID/PAYMENT_FAILED, hạn hủy 120 phút ở BE, chatbot Gemini + SSE (RA_SOAT_BAO_CAO_VS_CODE.md A6, A7, A9, A10, C2, C3, C16). | F35: Bắt buộc
A36: Có liệt kê các chức năng sản phẩm trong tài liệu không? | B36: x | E36: CHUONG_I_DAC_TA.md 3.1 (:177-201) có 23 UC tổng quan. MUC_LUC_BAO_CAO.md mục 3 (:216-320) có danh sách chức năng kiểm kê từ code (controller, endpoint, trang FE, listener, scheduler). | F36: Bắt buộc
A37: Các chức năng sản phẩm được liệt kê này: | C37: x | E37: Đạt tiêu chí phân nhóm nhưng không đạt tiêu chí mô tả chính xác (xem 2 dòng dưới). | F37: Bắt buộc
A38: Có được phân nhóm một cách hợp lý? | B38: x | E38: Chương I nhóm theo tác nhân. MUC_LUC_BAO_CAO.md 2.1 (:131-144) nhóm theo 10 phân hệ PH1-PH10, mục 3 nhóm theo vai trò (Khách hàng / Admin-Staff / Tự động / Hạ tầng). Hai cách nhóm (7 nghiệp vụ ở Chương I và 10 phân hệ ở MUC_LUC) chưa được đối chiếu với nhau.
A39: Có được mô tả một cách chính xác không? | C39: x | E39: RA_SOAT_BAO_CAO_VS_CODE.md: 6 UC không tồn tại (B1-B6: Trade-In, cửa hàng, Select Cart Items, Enter Cancellation Reason, Verify Refund Webhook); nghiệp vụ sai (B7-B19). Ví dụ: tìm kiếm văn bản thực tế là Elasticsearch findByNameContainingOrDescriptionContaining + fallback MariaDB, không phải hybrid BM25+e5+RRF (A8); chatbot dùng DeepSeek, trả JSON, không stream (A9).
A40: Danh sách Nhóm người / Người sử dụng có được đề cập theo các yêu cầu / chức năng này này không? | B40: x | E40: CHUONG_I_DAC_TA.md Bước 2 (:88-93) gắn chức năng với từng nhóm. Các UC tổng quan (:179-201) đều nêu tác nhân.
A41: Vai trò của Nhóm người / Người sử dụng có được ghi nhận không? | B41: x | E41: CHUONG_I_DAC_TA.md:7-15 mô tả vai trò 8 tác nhân. Nhưng code chỉ có 3 role Keycloak ROLE_ADMIN/ROLE_STAFF/ROLE_CUSTOMER (BE/keycloak-data/ecommerce-realm-realm.json). Nhân viên kho, Sales, Manager, Supplier không tồn tại (RA_SOAT_BAO_CAO_VS_CODE.md A4). Chỉ MUC_LUC_BAO_CAO.md:147 ghi đúng 4 nhóm người dùng.
A42: Có mô hình / Sơ đồ Tổng thể hệ thống không? | B42: x | E42: docs/services/00_INDEX.md:37-94 có sơ đồ mermaid kiến trúc tổng thể. uc_tong_quan.puml là sơ đồ UC tổng quan. Sơ đồ 00_INDEX thiếu chat-service, Debezium, forecast-service và vẽ sai 'User Service → MongoDB chat_messages'.
...

Sheet Phần_1-Review TL thiết kế
A1: Checklist Review Tài liệu Thiết kế
A3: Mã dự án | B3: TECHSTORE_2026
A4: Phiên bản sản phẩm | B4: v1.0
A5: Lần xem xét | B5: 1
A6: Người xem xét
A7: Ngày xem xét | B7: 17/10/2026
A8: Độ lớn sản phẩm | B8: Chương III (1.791 dòng: 47 lớp thực thể, 43 bảng, thiết kế tĩnh + động 7 module, 38 hình) + 25 tệp puml thiết kế; docs/services 11 tệp (~5.370 dòng) + DETAILED_ORDER_FLOW.md (449 dòng)
A9: Nguồn lực dành cho xem xét (MH) | B9: 10
A11: Câu hỏi | B11: Có | C11: Không | D11: N/A | E11: Ghi chú | F11: Điều kiện
A12: Kiểm soát tài liệu
A13: Tài liệu có tuân thủ theo yêu cầu kiểm soát tài liệu không: | C13: x | E13: CHUONG_III_PHA_THIET_KE.md, puml/, docs/services/*.md, docs/DETAILED_ORDER_FLOW.md đều là Markdown/PlantUML, không có mã hiệu, người lập/duyệt, ngày ban hành. | F13: Bắt buộc
A14: Mẫu tài liệu có phải là mẫu mới nhất không? | C14: x | E14: CHUONG_III_PHA_THIET_KE.md theo khung phương pháp luận PTTKHTTT (QUY_CHUAN_THIET_KE_PARADIGM.md): lớp thực thể (3 bước) → CSDL (5 bước) → thiết kế tĩnh/động 7 module → package/deployment. Đây không phải mẫu tài liệu thiết kế (SDD). Mỗi file docs/services có bố cục riêng. | F14: Bắt buộc
A15: Trang tiêu đề có đầy đủ: Tên gọi dự án, tên tài liệu, phiên bản, tên công ty và logo, mã dự án, mã hiệu tài liệu và thời gian ban hành không? | C15: x | E15: Chỉ có heading '# CHƯƠNG III. PHA THIẾT KẾ' (CHUONG_III_PHA_THIET_KE.md:1) và '# TÀI LIỆU THIẾT KẾ: …' ở docs/services. Không có công ty, logo, mã dự án, mã hiệu, ngày ban hành. | F15: Bắt buộc
A16: Đầu và cuối trang có bao gồm tên, phiên bản của tài liệu không? | C16: x | E16: Markdown không có header/footer. | F16: Bắt buộc
A17: Đánh số trang có theo đúng quy định: số thứ tự/tổng số trang? | C17: x | E17: Markdown không đánh số trang. | F17: Bắt buộc
A18: Trang ký có đầy đủ và đúng Người lập tài liệu, Người xem xét, Người phê duyệt như ghi nhận trong KHDA không? | C18: x | E18: Không có trang ký. | F18: Bắt buộc
A19: Có bảng ghi nhận thay đổi không? | C19: x | E19: Không có. Có dấu hiệu nhiều phiên bản nhưng không ghi lại: CHUONG_III_PHA_THIET_KE.md dùng nhãn 'Kịch bản v3.0' (:1329, :1397, :1455, :1507…); 00_INDEX.md:15 ghi 'Phiên bản 1.0.0 | Cập nhật 2026-06-01'; 01_IDENTITY_USER_SERVICE.md:14 ghi 'Version: 2.0.0'; banner rà soát 2026-10-11. | F19: Bắt buộc
A20: Đối với trường hợp phiên bản tài liệu > v1.0: | D20: x | E20: Bộ tài liệu được xem xét ở phiên bản v1.0. Nên thống nhất lại các nhãn v3.0/2.0.0 nêu ở dòng trên. | F20: Bắt buộc
A21: Các nội dung ghi nhận trong Bảng ghi nhận thay đổi này có đầy đủ và đúng không? | D21: x | E21: Không áp dụng (không có bảng ghi nhận thay đổi). | F21: Bắt buộc
A22: Tổng quan tài liệu – Giới thiệu chung
A23: Mục đích có bao gồm: | C23: x | E23: Có mục tiêu (1 câu dẫn), không có đối tượng sử dụng (xem 2 dòng dưới).
A24: Mục tiêu của tài liệu? | B24: x | E24: Chỉ có một câu dẫn ở CHUONG_III_PHA_THIET_KE.md:7 ('cụ thể hóa cấu trúc hướng đối tượng … sẵn sàng chuyển giao sang mã nguồn Java Spring Boot và cơ sở dữ liệu'). docs/services có mục 'I. Tổng quan và nhiệm vụ' nói về nhiệm vụ service, không phải mục tiêu tài liệu. | F24: Bắt buộc
A25: Đối tượng sử dụng tài liệu? | C25: x | E25: Không nêu người đọc (dev, tester, hội đồng…). | F25: Bắt buộc
A26: Phạm vi có bao gồm các nội dung: | C26: x | E26: Đạt 2/3 tiêu chí con. Thiếu danh sách đầy đủ chức năng được thiết kế (xem dòng dưới).
A27: Liệt kê đầy đủ các chức năng mà sản phẩm phần mềm sẽ xây dựng? | C27: x | E27: CHUONG_III_PHA_THIET_KE.md mục 3 chỉ thiết kế 7 module (3.1 a-g). Không thiết kế user, inventory, notification, review, analytics/forecast (RA_SOAT_BAO_CAO_VS_CODE.md D21). docs/services có 10 service nhưng 09_AI_ENGINE_SERVICE.md đã lỗi thời và không có forecast-service (00_INDEX.md:32). | F27: Bắt buộc
A28: Xác định phạm vi các phân hệ / chức năng thuộc sản phẩm phần mềm dự kiến sẽ đáp ứng? | B28: x | E28: 7 module trong CHUONG_III_PHA_THIET_KE.md mục 3; bảng 10 service, port, DB ở 00_INDEX.md:20-33. | F28: Bắt buộc
A29: Mô tả kết quả và mục tiêu dự kiến đạt được của mỗi chức năng / phân hệ thuộc phần mềm? | B29: x | E29: Mục 'I. Tổng quan và nhiệm vụ' của từng file docs/services. Kịch bản v3.0 của từng module trong Chương III mô tả kết quả cuối luồng. | F29: Bắt buộc
A30: Có bảng thuật ngữ và khái niệm không? | C30: x | E30: CHUONG_III_PHA_THIET_KE.md không có. Chỉ Chương I mục 1 có bảng từ khóa nghiệp vụ, thiếu thuật ngữ kỹ thuật dùng dày đặc trong thiết kế: Outbox, CDC, Saga, gRPC, JWT, Idempotency, SASRec, FAISS, RRF. | F30: Bắt buộc
A31: Có liệt kê các tài liệu tham khảo không? | C31: x | E31: Không có danh mục tham khảo. Chỉ có liên kết tới file puml/png (đều trỏ file:///d:/Downloads/…) và liên kết chéo giữa các file docs/services.
A32: Nếu có, mỗi tài liệu có bao gồm các thông tin sau không? | D32: x | E32: Không có danh mục tài liệu tham khảo.
A33: Tên tài liệu | D33: x | E33: Không có danh mục tài liệu tham khảo.
A34: Ngày phát hành | D34: x | E34: Không có danh mục tài liệu tham khảo.
A35: Nguồn | D35: x | E35: Không có danh mục tài liệu tham khảo.
A36: Có mô tả tổ chức của tài liệu không? | B36: x | E36: 00_INDEX.md:20-33 liệt kê 10 tài liệu service. CHUONG_III_PHA_THIET_KE.md nêu trình tự các bước (:7, :478, :722). Chưa có đoạn mô tả tổng thể cấu trúc Chương III. | F36: Bắt buộc
A37: Thiết kế Kiến trúc
A38: Thiết kế kiến trúc chung
A39: Kiến trúc hệ thống có độc lập với công nghệ sử dụng để dễ dàng thay đổi không? | B39: x | E39: Kiến trúc microservices giao tiếp qua REST/gRPC/Kafka, đa ngôn ngữ (Java + Python FastAPI), mỗi service một DB; việc đổi PostgreSQL → MariaDB thực tế không phải đổi kiến trúc. Nhưng CHUONG_III_PHA_THIET_KE.md:722-727 mô tả kiến trúc gắn chặt thuật ngữ Spring, không có góc nhìn kiến trúc độc lập công nghệ.
A40: Kiến trúc hệ thống có tính đến mọi ràng buộc kỹ thuật hoặc ràng buộc khác không thể tránh được không? (nghĩa là có khả thi cho môi trường đã chọn không) | C40: x | E40: deployment_diagram.puml chỉ có 3 node, ghi PostgreSQL 16, Mongo 7.0, Redis 7.2, ES 8.13, Kafka + Zookeeper (CHUONG_III_PHA_THIET_KE.md:1776-1780). Code dùng mariadb:10.11, mongo:6.0, redis:7.0-alpine, elasticsearch:8.10.2, cp-kafka:7.4.0 chạy KRaft (BE/docker-compose-infra.yml:11-195) (RA_SOAT_BAO_CAO_VS_CODE.md A1, D17). Không nêu ràng buộc tài nguyên (RAM cho ES, Kafka, 4 service AI PyTorch). | F40: Bắt buộc
A41: Các yêu cầu ảnh hưởng đến kiến trúc có được mô tả không? | B41: x | E41: Chỉ ở docs/services: chống overselling (04 §II, §VII so sánh concurrency control), cache-aside (02 §II), exactly-once qua outbox (03 §VII), rate limit API AI (08 §V). CHUONG_III_PHA_THIET_KE.md không có mục yêu cầu kiến trúc. | F41: Bắt buộc
A42: Ngôn ngữ lập trình và công nghệ đã chọn có phù hợp không? | B42: x | E42: Java 17 + Spring Boot 3.2.5/Spring Cloud, Python FastAPI cho AI, Kafka + Debezium, Redis, Elasticsearch, Keycloak, Camunda 7: phù hợp TMĐT phân tán. Tài liệu ghi sai: Next.js/Bootstrap thay cho React 19 + Vite 7 + Tailwind; vẽ class Java cho search/recs/chatbot vốn viết bằng Python (RA_SOAT_BAO_CAO_VS_CODE.md A3, mục E). | F42: Bắt buộc
...

Sheet Phần_1-Review TL HD cài đặt
A1: Checklist Review Tài liệu Hướng dẫn Cài đặt (IM)
A3: Mã dự án | B3: TECHSTORE_2026
A4: Phiên bản sản phẩm | B4: v1.0
A5: Lần xem xét | B5: 1
A6: Người xem xét
A7: Ngày xem xét | B7: 17/10/2026
A8: Độ lớn sản phẩm | B8: 6 file hướng dẫn (~1.140 dòng Markdown) cho 8 microservice Java + Eureka + API Gateway, 4 service AI, Frontend React và hạ tầng Docker
A9: Nguồn lực dành cho xem xét (MH) | B9: 4
A11: Câu hỏi | B11: Có | C11: Không | D11: N/A | E11: Ghi chú | F11: Điều kiện
A12: Kiểm soát tài liệu
A13: Tài liệu có tuân thủ theo yêu cầu kiểm soát tài liệu không: | C13: x | E13: Hướng dẫn cài đặt nằm rải rác ở 6 file Markdown (README.md, BE/README.md, BE/DEPLOY.md, AI/README.md, FE/README.md, docs/keycloak_setup_guide.md); không file nào có mã hiệu, phiên bản, ngày ban hành hay người phê duyệt. | F13: Bắt buộc
A14: Mẫu tài liệu có phải là mẫu mới nhất không? | C14: x | E14: Không sử dụng biểu mẫu Installation Manual nào; đây là README dành cho lập trình viên. | F14: Bắt buộc
A15: Trang tiêu đề có đầy đủ: Tên gọi dự án, tên tài liệu, phiên bản, tên công ty và logo, mã dự án, mã hiệu tài liệu và thời gian ban hành không? | C15: x | E15: Mỗi file chỉ có tiêu đề H1. Tên sản phẩm không thống nhất: README.md ghi 'AuraTech', BE/README.md và FE/README.md ghi 'TECHSTORE'. Không có phiên bản, đơn vị/logo, mã dự án, mã hiệu, ngày ban hành. | F15: Bắt buộc
A16: Đầu và cuối trang có bao gồm tên, phiên bản của tài liệu không? | C16: x | E16: Markdown không có header/footer. | F16: Bắt buộc
A17: Đánh số trang có theo đúng qui định: số thứ tự/tổng số trang? | C17: x | E17: Không có số trang (Markdown hiển thị trên GitHub/IDE). | F17: Bắt buộc
A18: Trang ký có đầy đủ và đúng Người lập tài liệu, Người xem xét, Người phê duyệt như ghi nhận trong KHDA không? | C18: x | E18: Không có trang ký ở cả 6 file. | F18: Bắt buộc
A19: Có bảng ghi nhận thay đổi không? | C19: x | E19: Không có Change History. BE/DEPLOY.md chỉ có mục 'Lịch sử phát hiện bảo mật (17/7/2026)', docs/keycloak_setup_guide.md có ghi chú 'rà soát 2026-10-11' — không phải bảng ghi nhận thay đổi. | F19: Bắt buộc
A20: Đối với trường hợp phiên bản tài liệu > v1.0: | D20: x | E20: Tài liệu không ghi phiên bản; coi là bản đầu nên không áp dụng. | F20: Bắt buộc
A21: Các nội dung ghi nhận trong Bảng ghi nhận thay đổi này có đầy đủ và đúng không? | D21: x | E21: Không có bảng ghi nhận thay đổi nên không áp dụng. | F21: Bắt buộc
A22: Tổng quan Tài liệu
A23: Có ghi nhận Mục tiêu Tài liệu không? | B23: x | E23: BE/README.md (câu mở đầu: hướng dẫn cấu hình môi trường và khởi chạy Backend theo 2 phương pháp), BE/DEPLOY.md (ghi lại các bước deploy production để làm lại từ đầu), FE/README.md. README.md gốc không có câu mục tiêu. | F23: Bắt buộc
A24: Kiểm tra nội dung Mục tiêu Tài liệu có được ghi nhận đủ gồm: | C24: x | E24: Chỉ có nội dung mục tiêu, thiếu đối tượng sử dụng (xem 2 dòng dưới).
A25: Nội dung của mục tiêu? | B25: x | E25: BE/README.md: Full Docker và Hybrid; BE/DEPLOY.md: deploy AWS EC2; FE/README.md: chạy local bằng Vite. | F25: Bắt buộc
A26: Đối tượng sử dụng tài liệu? | C26: x | E26: Chỉ ngầm hiểu là lập trình viên (BE/README.md mục III: 'tối ưu nhất cho nhà phát triển'); không xác định người vận hành/quản trị hệ thống hay người kiểm thử. | F26: Bắt buộc
A27: Có bảng thuật ngữ và từ viết tắt sử dụng trong tài liệu không? | C27: x | E27: Không có; nhiều thuật ngữ không giải thích: Saga, Outbox, Debezium, KRaft, IPN, RRF, FAISS, SASRec, IGNORE_EXISTING. | F27: Bắt buộc
A28: Có mô tả kiến trúc Hệ thống sẽ Cài đặt không? | B28: x | E28: README.md dòng Stack + bảng port 8 service; BE/README.md mô tả thành phần chạy trong Docker; AI/README.md mục 1 cây thư mục 4 service AI (8001–8004). Chưa có sơ đồ triển khai tổng thể/bản đồ port của hạ tầng (MariaDB, Kafka, Keycloak 8083…).
A29: Có mô tả tổ chức / cấu trúc của tài liệu không? | C29: x | E29: Không có mục lục chung; README.md gốc chỉ liên kết tới AI/README.md, docs/AI/*.md và tools/catalog-import/README.md, không liên kết BE/README.md, FE/README.md, BE/DEPLOY.md, docs/keycloak_setup_guide.md. | F29: Bắt buộc
A30: Yêu cầu về Môi trường Cài đặt
A31: Có mô tả Yêu cầu về môi trường máy chủ (Server) không? | B31: x | E31: BE/DEPLOY.md mục 0–2: EC2 m7i-flex.large (2 vCPU/8 GB), Ubuntu 22.04/24.04, 50 GB gp3, Docker, Node.js 20, OpenJDK 17, Maven. | F31: Bắt buộc
A32: Cấu hình tối thiểu có được ghi nhận đầy đủ và đúng không? | C32: x | E32: DEPLOY.md mục 0 ghi cấu hình đã dùng, không phải cấu hình tối thiểu; cấu hình 8 GB đó không chạy 4 service AI (mục 9 không khởi động AI, bỏ cả kafka-ui/kibana vì thiếu RAM). Không có yêu cầu RAM/CPU/ổ đĩa cho chạy full Docker local (BE + AI với model CLIP/e5-large). | F32: Bắt buộc
A33: Các phần mềm cài đặt cần thiết có được liệt kê tương ứng không? | B33: x | E33: BE/README.md mục I (JDK 17, Maven 3.8+, Docker Compose 2.x, IntelliJ), FE/README.md mục I (Node.js v18+), DEPLOY.md mục 2. Mâu thuẫn Node: FE/README.md 'v18 trở lên' nhưng DEPLOY.md mục 2 coi v18 là chưa cài thành công (yêu cầu v20). Không nêu JDK 17 là bắt buộc (thực tế Lombok 1.18.30 không biên dịch được trên JDK 23); AI/README.md không nêu phiên bản Python (Dockerfile dùng python:3.10-slim). | F33: Bắt buộc
A34: Có mô tả Yêu cầu về môi trường máy chủ CSDL không? | B34: x | E34: Không có mục riêng: CSDL (MariaDB, MongoDB, Redis, Elasticsearch) chạy dạng container trong cùng docker-compose; README.md dòng Stack và DEPLOY.md mục 7 (MariaDB, keycloak_db) có đề cập.
A35: Nếu có, cấu hình tối thiểu đối với môi trường Máy chủ CSDL có được ghi nhận đầy đủ và đúng không? | C35: x | E35: Không có cấu hình RAM/ổ đĩa cho MariaDB/MongoDB/Elasticsearch; DEPLOY.md mục 10 chỉ nhắc kiểm tra mem_limit bằng docker stats. | F35: Bắt buộc
A36: Các phần mềm cài đặt cần thiết có được liệt kê tương ứng không? | B36: x | E36: README.md liệt kê MariaDB · MongoDB · Redis · Kafka · Elasticsearch · MinIO · Keycloak 24.x nhưng chỉ Keycloak có phiên bản; phiên bản thật nằm trong compose. BE/docker-compose.yml và docker-compose-infra.yml dùng minio/minio:latest không ghim phiên bản — tuần này image này không pull được từ Docker Hub/Quay, phải thay bằng pgsty/minio. | F36: Bắt buộc
A37: Có mô tả Yêu cầu về môi trường máy trạm không? | B37: x | E37: Máy phát triển/local: BE/README.md mục I và FE/README.md mục I 'Yêu cầu hệ thống cần cài đặt cục bộ'. Không nêu yêu cầu trình duyệt cho người dùng cuối.
A38: Nếu có, cấu hình tối thiểu đối với môi trường Máy trạm có được ghi nhận đầy đủ và đúng không? | C38: x | E38: Không nêu hệ điều hành, RAM, CPU, ổ đĩa cho máy local, trong khi full stack BE (~20 container) + AI cần nhiều RAM (Test Plan mục 6 đánh giá rủi ro thiếu RAM mức Cao trên máy 24 GB). | F38: Bắt buộc
A39: Các phần mềm cài đặt cần thiết có được liệt kê tương ứng không? | B39: x | E39: JDK 17, Maven, Docker, IntelliJ, Node.js, npm được liệt kê; thiếu Git, phiên bản Python cho AI/README.md mục 3, và cảnh báo không dùng JDK > 17. | F39: Bắt buộc
A40: Quy trình Cài đặt
A41: Mô tả chung có các nội dung sau đây không: | B41: x | E41: Xem các dòng con.
A42: Các Database sẽ cài đặt trong Hệ thống? | B42: x | E42: Chỉ liệt kê tên engine (README.md dòng Stack, bước 2 Hybrid 'DB, Kafka, Redis, MinIO, Keycloak...'); không có danh sách database/schema theo từng service, ngoại trừ keycloak_db tạo tay ở DEPLOY.md mục 7. | F42: Bắt buộc
...

Sheet PH1-Review SRS
A1: SRS Review Checklist
A3: Mã dự án | B3: TECHSTORE_2026
A4: Phiên bản sản phẩm | B4: v1.0
A5: Phân hệ / Module | B5: PH1 – Tài khoản, xác thực & phân quyền
A6: Lần xem xét | B6: 1
A7: Người xem xét
A8: Ngày xem xét | B8: 17/10/2026
A9: Độ lớn sản phẩm | B9: 3 Use Case tổng quan (Login, Manage Profile, Manage Account) + 2 UC con (Employee Login, Customer Login); 0 kịch bản chi tiết trong Chương II; 3 tài liệu thiết kế (~900 dòng)
A10: Nguồn lực dành cho xem xét (MH) | B10: 4
A11: Tài liệu được xem xét | B11: docs/services/01_IDENTITY_USER_SERVICE.md (v2.0.0, banner rà soát 2026-10-11); docs/services/08_API_GATEWAY_DISCOVERY.md (v1.0.0); docs/system_roles_permissions.md; CHUONG_I_DAC_TA.md §1 (từ khoá 1-8, 32-34), §2 Bước 1-5, §3.1 (UC Login, Manage Profile, Manage Account); CHUONG_II_PHA_PHAN_TICH.md §2 Bước 3 mục a (lớp tác nhân); đối chiếu RA_SOAT_BAO_CAO_VS_CODE.md mục A4, A5, A17, B21, B25, C22, C23, E5
A13: Câu hỏi | B13: Có | C13: Không | D13: N/A | E13: Ghi chú | F13: Điều kiện
A14: Kiểm soát tài liệu
A15: Tài liệu có tuân thủ theo yêu cầu kiểm soát tài liệu không: | C15: x | E15: Các file là markdown trong repo, không có mã hiệu tài liệu, người lập/duyệt hay ngày ban hành. 01 chỉ ghi 'Version: 2.0.0' và banner rà soát 2026-10-11. | F15: Bắt buộc
A16: Mẫu tài liệu có phải là mẫu mới nhất không? | C16: x | E16: Không dùng mẫu SRS chuẩn: mỗi file docs/services có bố cục riêng (I. Tổng quan … VII. Docker), còn Chương I theo đề cương đồ án. | F16: Bắt buộc
A17: Trang tiêu đề có bao gồm đủ tên tài liệu, phiên bản, tên công ty và logo, mã dự án, mã hiệu tài liệu và thời gian ban hành không? | C17: x | E17: Chỉ có heading '# TÀI LIỆU THIẾT KẾ: IDENTITY & USER SERVICE' và dòng Port/DB/Version; không có công ty, logo, mã dự án, mã hiệu hay ngày ban hành. | F17: Bắt buộc
A18: Đầu và cuối trang có bao gồm tên, phiên bản của tài liệu, Mã hiệu của template không? | C18: x | E18: Markdown không có header/footer trang. | F18: Bắt buộc
A19: Đánh số trang có theo đúng qui định: số thứ tự/tổng số trang? | C19: x | E19: Markdown không đánh số trang. | F19: Bắt buộc
A20: Trang ký có bao gồm đủ Người xem xét & Người phê duyệt không? | C20: x | E20: Không có trang ký nào trong 3 tài liệu và trong Chương I. | F20: Bắt buộc
A21: Có bảng theo dõi lịch sử thay đổi không? | C21: x | E21: Không có bảng lịch sử. Chỉ có banner 'Thiết kế ban đầu — một số phần KHÔNG khớp với code hiện tại (rà soát 2026-10-11)' ở đầu 01/08 và một dòng ghi chú rà soát trong system_roles_permissions.md. | F21: Bắt buộc
A22: Đối với trường hợp phiên bản tài liệu > v1.0: | C22: x | E22: 01 ghi Version 2.0.0 (> v1.0) nhưng không ghi lại thay đổi so với 1.x. | F22: Bắt buộc
A23: Các nội dung ghi nhận trong Bảng ghi nhận thay đổi này có đầy đủ và đúng không? | D23: x | E23: Không có bảng ghi nhận thay đổi để đối chiếu. | F23: Bắt buộc
A24: Giới thiệu chung
A25: Có nêu rõ mục đích của tài liệu không? | B25: x | E25: system_roles_permissions.md đoạn đầu nêu rõ 'Tài liệu này xác định chi tiết quyền hạn truy cập của 3 nhóm vai trò'. 01 §I.1.1 và 08 §I chỉ nêu nhiệm vụ của service, không nêu mục đích của tài liệu. | F25: Bắt buộc
A26: Phạm vi hệ thống có được mô tả rõ ràng không? | B26: x | E26: Chương I §2 Bước 2 liệt kê phạm vi theo tác nhân (Thành viên: đăng nhập, đăng xuất, đổi mật khẩu…; Quản trị viên: quản lý tài khoản, khóa/mở). 01 §1.1 có bảng nhóm chức năng. Tuy vậy Bước 2 có tác nhân 'Nhân viên kho' không tồn tại (RA_SOAT A4). | F26: Bắt buộc
A27: Các khái niệm và thuật ngữ có được định nghĩa đầy đủ không? | C27: x | E27: Chương I §1 có bảng từ khoá nghiệp vụ (Thành viên, Khách hàng, Đăng ký, Đăng nhập…), nhưng thuật ngữ kỹ thuật của PH1 trong 01/08 (OIDC, JWKS, realm role, RBAC, X-User-*, auto-provision) không được định nghĩa. | F27: Bắt buộc
A28: Có liệt kê các tài liệu tham khảo không? | C28: x | E28: Không có mục tài liệu tham khảo; link puml trong Chương I §3.1 trỏ tới file:///d:/Downloads/... trên máy cá nhân (RA_SOAT A17). | F28: Bắt buộc
A29: Nếu có, mỗi tài liệu có bao gồm các thông tin sau không? | D29: x | E29: Không có danh mục tài liệu tham khảo.
A30: Tên tài liệu | D30: x | E30: Không có danh mục tài liệu tham khảo.
A31: Ngày phát hành | D31: x | E31: Không có danh mục tài liệu tham khảo.
A32: Nguồn | D32: x | E32: Không có danh mục tài liệu tham khảo.
A33: Có mô tả giới hạn của tài liệu không? | C33: x | E33: Không có mục giới hạn. Banner ở 01/08 có liệt kê các phần lệch code, nhưng chưa phải phát biểu giới hạn phạm vi tài liệu. | F33: Bắt buộc
A34: Có mô tả tổ chức của tài liệu không? | C34: x | E34: Chỉ có các heading I…VII, không có đoạn giới thiệu cấu trúc tài liệu. | F34: Bắt buộc
A35: Mô tả tổng thể
A36: Có xác định ngữ cảnh và điều kiện sử dụng của hệ thống (scenarios and operational concepts) không? | B36: x | E36: 01 §1.2 có sơ đồ luồng OIDC Client → Keycloak :8083 → Gateway :8080 → User Service :8085; 08 §II có luồng routing & security. Tuy nhiên Chương I Bước 3 không có luồng nghiệp vụ cho Đăng nhập/Quản lý tài khoản. | F36: Bắt buộc
A37: Có liệt kê các chức năng sản phẩm trong tài liệu không? | B37: x | E37: 01 §1.1 và §5.2/§5.4 liệt kê API hồ sơ, địa chỉ, điểm, nội bộ; Chương I §3.1 có UC Login, Manage Profile, Manage Account. | F37: Bắt buộc
A38: Các chức năng sản phẩm được liệt kê này: | B38: x | E38: Đánh giá chi tiết ở 2 câu con bên dưới. | F38: Bắt buộc
A39: Có được phân nhóm một cách hợp lý? | B39: x | E39: 01 §1.1 nhóm theo IAM / JWKS / RBAC / đồng bộ hồ sơ / thông tin mở rộng; system_roles §2.1 nhóm endpoint của user-service theo vai trò. | F39: Bắt buộc
A40: Có được mô tả một cách chính xác không? | C40: x | E40: 01 §2.2 (Keycloak SPI → Kafka) và §2.3 (tự nâng hạng/cộng điểm theo đơn) không có trong code; Chương I Bước 4 có ngày sinh, giới tính, mật khẩu của Thành viên không có trong User.java (RA_SOAT A5, B21); banner 08 gọi UserHeaderFilter là GlobalFilter trong khi code implements WebFilter (UserHeaderFilter.java:42). | F40: Bắt buộc
A41: Danh sách Nhóm người / Người sử dụng có được đề cập theo các yêu cầu / chức năng này này không? | B41: x | E41: system_roles §2.1 ghi rõ CUSTOMER/STAFF/ADMIN cho từng endpoint user-service. Chương I lại dùng 6 tác nhân (có Nhân viên kho, Manager, Supplier) không khớp 3 role của realm.
A42: Vai trò của Nhóm người / Người sử dụng có được ghi nhận không? | B42: x | E42: system_roles §1 mô tả trách nhiệm của ROLE_ADMIN, ROLE_STAFF, ROLE_CUSTOMER; Chương I §1 mục I mô tả các nhóm người.
...

Sheet PH1-Review Code
A1: Code Review Checklist
A3: Mã dự án: | B3: TECHSTORE_2026
A4: Thành phần được xem xét: | B4: user-service (BE/user-service/src/main/java/com/ecommerce/userservice/), api-gateway (BE/api-gateway/src/main/java/com/ecommerce/apigateway/ config + filter), BE/keycloak-data (realm export)
A5: Phiên bản: | B5: v1.0
A6: Lần xem xét: | B6: 1
A7: Người xem xét:
A8: Ngày xem xét: | B8: 17/10/2026
A9: Độ lớn sản phẩm được xem xét: | B9: 33 file đã xem: user-service 24 (4 controller, 5 service/impl + LoyaltyPointPolicy, KeycloakAdminClient, SecurityConfig, InternalApiKeyFilter, RestTemplateConfig, 2 entity, UserRepository, GlobalExceptionHandler, 5 DTO request, UserEventProducer, application.yml), api-gateway 7 (SecurityConfig, UserHeaderFilter, RateLimiterConfig, WebClientConfig, CorsConfig, FallbackController, application.yml), keycloak-data 2 file JSON; khoảng 2.500 dòng Java
A10: Nhân công dành cho xem xét (MH): | B10: 4
A12: Câu hỏi | B12: Có | C12: Không | D12: N/A | E12: Ghi chú
A13: Tổng quan
A14: Code có được viết tốt không (về mặt hình thức) ? Đọc có dễ hiểu không? | B14: x | E14: Phân tầng controller/service/repository rõ, dùng Lombok và DTO request/response riêng. Riêng UserServiceImpl.java dài 559 dòng gộp cả đồng bộ hồ sơ, CRUD admin và đồng bộ Keycloak nên khó theo dõi.
A15: Các ghi chú và chuẩn lập trình
A16: Code có thực hiện theo đúng chuẩn lập trình không? | B16: x | E16: Tuân theo quy ước Java/Spring. Còn vài chỗ lệch: dùng tên lớp đầy đủ thay vì import (UserServiceImpl.java:28-29, :133; UserController.java:50), @Data trên entity JPA (User.java:10) sinh equals/hashCode theo mọi trường.
A17: Tên biến | B17: x | E17: camelCase, có nghĩa: keycloakUserId, currentBalance, newBalance (LoyaltyPointServiceImpl.java:76-77). Chỉ vài tên viết tắt cục bộ như kcUser, tx.
A18: Căn lề | B18: x | E18: Thụt lề 4 khoảng trắng đồng nhất ở cả user-service và api-gateway; chỉ có vài dòng trống chứa khoảng trắng thừa (UserServiceImpl.java:57).
A19: Kiểu dấu ngoặc | B19: x | E19: Kiểu K&R nhất quán. KeycloakAdminClient.java:84-85, :121-122, :127-128 viết try/catch trên một dòng, khác phong cách phần còn lại.
A20: Các file source có đầy đủ tiêu đề đầu trang và thông tin bản quyền không? | C20: x | E20: Không file nào có header tác giả/ngày/bản quyền; file bắt đầu thẳng bằng package (vd UserServiceImpl.java:1, UserHeaderFilter.java:1).
A21: Các khai báo biến có được ghi chú đúng cách không? | C21: x | E21: Chỉ một số trường entity có chú thích (User.java:38-55: customerTier, segmentationLabel, isBlacklisted, loyaltyPoints). Các trường cấu hình trong KeycloakAdminClient.java:28-38 và DTO như CreateUserRequest.java không có ghi chú.
A22: Các thành phần dữ liệu dạng số có được khai báo rõ ràng không? | B22: x | E22: Hằng tiền tệ được đặt tên và dùng BigDecimal (LoyaltyPointPolicy.java:17-18). Vẫn còn số magic: hệ số hạng 1.2/1.5/2.0 viết thẳng trong switch (LoyaltyPointPolicy.java:34-36), timeout 3 giây (UserHeaderFilter.java:127).
A23: Toàn bộ các functions, methods và classes có được ghi chú lại không | C23: x | E23: KeycloakAdminClient và AdminUserController có Javadoc từng hàm, nhưng UserServiceImpl, LoyaltyPointServiceImpl, AddressServiceImpl không có Javadoc cho hàm public nào.
A24: Các đoạn thuật toán phức tap và các đoạn tối ưu code có được ghi chú đầy đủ không? | B24: x | E24: Có giải thích việc liên kết tài khoản theo email (UserServiceImpl.java:39-42), lý do khóa PESSIMISTIC_WRITE (UserRepository.java:49-54), cache auto-provision trong Redis (UserHeaderFilter.java:22-38, :103-108).
A25: Các đoạn code được đánh dấu hủy bỏ có được giải thích không? | D25: x | E25: Đã grep toàn bộ user-service và api-gateway, không có đoạn code bị comment-out hay TODO/FIXME.
A26: Các ghi chú có được cập nhật kịp thời không? | C26: x | E26: UserServiceImpl.java:58-63 nói user có thể được getUserByKeycloakId() tạo với dữ liệu placeholder, nhưng hàm này nay chỉ ném lỗi (UserServiceImpl.java:167-173). user-service SecurityConfig.java:37-38 vẫn ghi 'nên thêm IP whitelist' dù InternalApiKeyFilter đã có.
A27: Các ghi chú có rõ ràng và đúng không? | C27: x | E27: Javadoc user-service SecurityConfig.java:17-24 nói tầng 2 'verify lại JWT' để an toàn khi bypass Gateway, nhưng controller lấy danh tính từ header X-User-Id (UserController.java:39) chứ không từ sub của JWT, nên lời giải thích này gây hiểu sai.
A28: Các ghi chú có tập trung vào giải thích tại sao chứ không phải như thế nào không? | B28: x | E28: Phần lớn comment nói lý do: vì sao khóa hàng khi trừ điểm (UserRepository.java:49-54), vì sao không đọc X-User-Id trong rate limiter (RateLimiterConfig.java:13-17), vì sao che username công khai (UserController.java:143-144).
A29: Tên của mỗi thủ tục/hàm/class có nói lên thủ tục/hàm/class đó làm gì hay không? | B29: x | E29: Đa số đúng (adjustPoints, redeemForOrder, maskForPublic). Ngoại lệ: getCurrentUser (UserServiceImpl.java:33) còn tạo mới, liên kết lại email và ghi DB, tên 'get' che giấu tác dụng phụ.
A30: Xử lý lỗi
A31: Có xử lý lỗi mỗi khi function return không? | C31: x | E31: Future của kafkaTemplate.send không được kiểm tra (UserEventProducer.java:37). getUserRealmRoles trả List rỗng khi lỗi (KeycloakAdminClient.java:126-129) nên setUserRoles (KeycloakAdminClient.java:142-147) không phân biệt được 'không có role' với 'gọi Keycloak lỗi'.
A32: Các trường hợp ngoại lệ có được xử lý không? | B32: x | E32: GlobalExceptionHandler.java ánh xạ ResourceNotFound→404, IllegalArgument→400, KeycloakSync→502, DataIntegrityViolation→409, validation→400, còn lại→500. Gateway có fallback circuit breaker (FallbackController.java).
A33: Các hàm gọi đến có được thông báo khi có lỗi không? | C33: x | E33: updateBlacklist nuốt lỗi Keycloak (UserServiceImpl.java:250-254) nên API vẫn trả 'Tài khoản đã bị khóa' trong khi user còn đăng nhập được; tương tự adminDeleteUser (UserServiceImpl.java:394-398) và adminUpdateUser (UserServiceImpl.java:372-379).
A34: Quản lý tài nguyên
A35: Các bộ nhớ được cấp phát có được giải phóng không? | D35: x | E35: Java/Spring dùng GC, không có cấp phát thủ công. Không thấy cache tự quản lý trong bộ nhớ ở user-service hay gateway.
A36: Toàn bộ các đối tượng (Database connections, Sockets, Files, etc.) có được giải phóng ngay cả trong trường hợp có lỗi không? | B36: x | E36: Dùng try-with-resources cho Response của Keycloak (KeycloakAdminClient.java:69), InputStream MinIO (MinioStorageServiceImpl.java:55) và file JSON tỉnh/thành (LocationService.java:38); kết nối DB do Spring quản lý. Riêng client Keycloak không được close() khi tắt ứng dụng (không có @PreDestroy).
A37: Có đối tượng nào được giải phóng > 1 lần không? | C37: x | E37: Không thấy close/delete lặp lại trên cùng một tài nguyên.
A38: Thread Safeness
A39: Việc thay đổi giá trị của các biến dùng trong nhiều thread có được đồng bộ không? | C39: x | E39: synchronized(keycloakUserId.intern()) nằm bên trong @Transactional (UserServiceImpl.java:32-36, :153-156) nên khóa được nhả trước khi commit; request song song vẫn có thể insert trùng, và khóa chỉ có tác dụng trong một JVM. redeemForOrder kiểm tra idempotency theo orderId khi chưa khóa (LoyaltyPointServiceImpl.java:157-168) và bảng loyalty_point_transactions không có unique (order_id, source_type), nên hai request đồng thời có thể trừ điểm 2 lần.
A40: Các đối tượng dùng trong nhiều thread có được đồng bộ không? | B40: x | E40: Bean singleton không giữ trạng thái thay đổi; client Keycloak (KeycloakAdminClient.java:40) và WebClient.Builder chỉ gán một lần lúc khởi tạo. adjustPoints khóa hàng user bằng findByIdForUpdate (LoyaltyPointServiceImpl.java:40, UserRepository.java:55-57).
A41: Có giải phóng các lock theo đúng thứ tự không? | C41: x | E41: Khóa monitor theo keycloakUserId được nhả khi ra khỏi khối synchronized, trước khi transaction bao ngoài commit (UserServiceImpl.java:36 so với :32), nên thứ tự nhả khóa và kết thúc transaction bị đảo.
A42: Có khả năng xảy ra deadlock hoặc tranh chấp lock không? | B42: x | E42: Ít khả năng deadlock vì chỉ có một khóa cho mỗi user. Có tranh chấp: thread giữ monitor trong lúc chờ DB (UserServiceImpl.java:36-55), và mọi thao tác điểm của cùng user phải xếp hàng qua PESSIMISTIC_WRITE (UserRepository.java:55).
...

Sheet PH1-Kiểm thử giao diện
A1: Module + Function List
A2: ID | B2: Tên | C2: Mô tả
A3: Phân hệ: PH1 – Tài khoản, xác thực & phân quyền
A4: FR_01 | B4: Đăng nhập, đăng ký & đăng xuất | C4: Đăng nhập/đăng ký qua Keycloak (theme techstore), đăng xuất, kiểm tra thông tin sai
A5: FR_02 | B5: Hồ sơ cá nhân & sổ địa chỉ | C5: Xem tổng quan hồ sơ, cập nhật họ tên/SĐT, thêm/xóa địa chỉ nhận hàng, responsive
A6: FR_03 | B6: Phân quyền truy cập | C6: Chặn khách chưa đăng nhập, chặn khách hàng vào /admin, quyền STAFF so với ADMIN
A7: FR_04 | B7: Quản lý khách hàng (Admin) | C7: Tab Customers: tìm kiếm, đổi hạng, đặt lại mật khẩu, tạo người dùng
A10: TEST CASE OVERVIEW
A11: Feature ID | B11: Feature Name | C11: Total | D11: Pending | E11: Pass | F11: Fail | G11: Errors | H11: Pass Rate | I11: UI/UX | J11: Function | K11: Negative | L11: Errors in UI/UX | M11: Errors in Function | N11: Errors in Negative
A12: FR_01 | B12: Đăng nhập, đăng ký & đăng xuất | C12: =COUNTIF($A$60:$A$88,"UI_PH1_FR01_*") -> 8 | D12: =COUNTIFS($A$60:$A$88,"UI_PH1_FR01_*",$G$60:$G$88,"Pending") -> 0 | E12: =COUNTIFS($A$60:$A$88,"UI_PH1_FR01_*",$G$60:$G$88,"Pass") -> 8 | F12: =COUNTIFS($A$60:$A$88,"UI_PH1_FR01_*",$G$60:$G$88,"Fail") -> 0 | G12: =SUMIFS($H$60:$H$88,$A$60:$A$88,"UI_PH1_FR01_*") -> 0 | H12: =IFERROR(E12/C12,0) -> 1 | I12: =COUNTIFS($A$60:$A$88,"UI_PH1_FR01_*",$C$60:$C$88,"UI/UX") -> 2 | J12: =COUNTIFS($A$60:$A$88,"UI_PH1_FR01_*",$C$60:$C$88,"Function") -> 2 | K12: =COUNTIFS($A$60:$A$88,"UI_PH1_FR01_*",$C$60:$C$88,"Negative") -> 4 | L12: =SUMIFS($H$60:$H$88,$A$60:$A$88,"UI_PH1_FR01_*",$C$60:$C$88,"UI/UX") -> 0 | M12: =SUMIFS($H$60:$H$88,$A$60:$A$88,"UI_PH1_FR01_*",$C$60:$C$88,"Function") -> 0 | N12: =SUMIFS($H$60:$H$88,$A$60:$A$88,"UI_PH1_FR01_*",$C$60:$C$88,"Negative") -> 0
A13: FR_02 | B13: Hồ sơ cá nhân & sổ địa chỉ | C13: =COUNTIF($A$60:$A$88,"UI_PH1_FR02_*") -> 8 | D13: =COUNTIFS($A$60:$A$88,"UI_PH1_FR02_*",$G$60:$G$88,"Pending") -> 0 | E13: =COUNTIFS($A$60:$A$88,"UI_PH1_FR02_*",$G$60:$G$88,"Pass") -> 5 | F13: =COUNTIFS($A$60:$A$88,"UI_PH1_FR02_*",$G$60:$G$88,"Fail") -> 3 | G13: =SUMIFS($H$60:$H$88,$A$60:$A$88,"UI_PH1_FR02_*") -> 3 | H13: =IFERROR(E13/C13,0) -> 0.625 | I13: =COUNTIFS($A$60:$A$88,"UI_PH1_FR02_*",$C$60:$C$88,"UI/UX") -> 2 | J13: =COUNTIFS($A$60:$A$88,"UI_PH1_FR02_*",$C$60:$C$88,"Function") -> 2 | K13: =COUNTIFS($A$60:$A$88,"UI_PH1_FR02_*",$C$60:$C$88,"Negative") -> 4 | L13: =SUMIFS($H$60:$H$88,$A$60:$A$88,"UI_PH1_FR02_*",$C$60:$C$88,"UI/UX") -> 1 | M13: =SUMIFS($H$60:$H$88,$A$60:$A$88,"UI_PH1_FR02_*",$C$60:$C$88,"Function") -> 1 | N13: =SUMIFS($H$60:$H$88,$A$60:$A$88,"UI_PH1_FR02_*",$C$60:$C$88,"Negative") -> 1
A14: FR_03 | B14: Phân quyền truy cập | C14: =COUNTIF($A$60:$A$88,"UI_PH1_FR03_*") -> 5 | D14: =COUNTIFS($A$60:$A$88,"UI_PH1_FR03_*",$G$60:$G$88,"Pending") -> 0 | E14: =COUNTIFS($A$60:$A$88,"UI_PH1_FR03_*",$G$60:$G$88,"Pass") -> 4 | F14: =COUNTIFS($A$60:$A$88,"UI_PH1_FR03_*",$G$60:$G$88,"Fail") -> 1 | G14: =SUMIFS($H$60:$H$88,$A$60:$A$88,"UI_PH1_FR03_*") -> 1 | H14: =IFERROR(E14/C14,0) -> 0.8 | I14: =COUNTIFS($A$60:$A$88,"UI_PH1_FR03_*",$C$60:$C$88,"UI/UX") -> 0 | J14: =COUNTIFS($A$60:$A$88,"UI_PH1_FR03_*",$C$60:$C$88,"Function") -> 1 | K14: =COUNTIFS($A$60:$A$88,"UI_PH1_FR03_*",$C$60:$C$88,"Negative") -> 4 | L14: =SUMIFS($H$60:$H$88,$A$60:$A$88,"UI_PH1_FR03_*",$C$60:$C$88,"UI/UX") -> 0 | M14: =SUMIFS($H$60:$H$88,$A$60:$A$88,"UI_PH1_FR03_*",$C$60:$C$88,"Function") -> 0 | N14: =SUMIFS($H$60:$H$88,$A$60:$A$88,"UI_PH1_FR03_*",$C$60:$C$88,"Negative") -> 1
