Workbook

Sheet Hướng dẫn
A1: BỘ TEST CASE TOÀN HỆ THỐNG TECHSTORE
A2: Phiên bản | B2: Nhánh develop · lập ngày 17/10/2026
A3: Số test case | B3: 186 ca, chia theo 10 phân hệ + hạ tầng, bảo mật, phi chức năng và luồng xuyên suốt.
A4: Nguồn | B4: docs/test/HUONG_DAN_TEST_THU_CONG.md, bổ sung ca ngoại lệ, bảo mật và phi chức năng theo code nhánh develop.
A6: Cách dùng
A7: 1. Chuẩn bị | B7: Khởi động hệ thống và đặt mật khẩu tài khoản test (xem bên dưới). Chạy nhóm SYS trước; nếu SYS lỗi thì các nhóm khác sẽ bị chặn.
A8: 2. Thực hiện | B8: Ở sheet 'Test case', làm theo cột 'Các bước thực hiện', so với 'Kết quả mong đợi' và 'Cách kiểm chứng'.
A9: 3. Ghi kết quả | B9: Chỉ điền vào 5 cột có tiêu đề màu vàng đậm (nền ô vàng nhạt): Kết quả thực tế, Trạng thái, Người test, Ngày test, Mã lỗi / Ghi chú.
A10: 4. Ghi lỗi | B10: Ca 'Không đạt' thì thêm một dòng ở sheet 'Ghi lỗi' và ghi mã lỗi đó vào cột 'Mã lỗi / Ghi chú'. Dòng xám đầu tiên của sheet 'Ghi lỗi' là ví dụ, xóa khi dùng.
A11: 5. Theo dõi | B11: Sheet 'Tổng hợp' tự đếm theo phân hệ và mức ưu tiên. Lọc cột Trạng thái hoặc Ưu tiên bằng bộ lọc ở dòng tiêu đề.
A12: Trước khi báo lỗi | B12: Xem sheet 'Hành vi đã biết': các hành vi ở đó là hiện trạng đã ghi nhận, không phải lỗi mới.
A14: Giá trị cột Trạng thái
A15: Chưa test | B15: Mặc định.
A16: Đạt | B16: Kết quả thực tế khớp kết quả mong đợi.
A17: Không đạt | B17: Có sai khác. Ghi lỗi ở sheet 'Ghi lỗi'.
A18: Bị chặn | B18: Không thực hiện được vì điều kiện chưa có (service chưa chạy, ca trước lỗi, thiếu dữ liệu).
A19: Bỏ qua | B19: Không áp dụng cho đợt test này (ví dụ chưa có Google Client ID).
A21: Địa chỉ
A22: Web (FE) | B22: http://localhost:5173
A23: API Gateway | B23: http://localhost:8080
A24: Eureka | B24: http://localhost:8761
A25: Keycloak | B25: http://localhost:8083 (Admin Console: realm master)
A26: Debezium Connect | B26: http://localhost:8088
A27: MinIO Console | B27: http://localhost:9001
A28: Elasticsearch | B28: http://localhost:9200
A29: MariaDB | B29: localhost:3308 (user/mật khẩu trong BE/.env)
A30: Swagger AI | B30: Search 8001/docs · Chatbot 8002/docs · Recs 8003/docs · Forecast 8004/docs
A32: Tài khoản test (realm ecommerce-realm)
A33: admin (ROLE_ADMIN) | B33: admin@gmail.com · mật khẩu 12345678 (đặt lại ngày 17/10/2026).
A34: staff (ROLE_STAFF) | B34: staff@gmail.com · chưa biết mật khẩu, đặt lại theo HUONG_DAN_TEST_THU_CONG.md §2.
A35: customer (ROLE_CUSTOMER) | B35: customer@gmail.com · chưa có mật khẩu, đặt lại theo HUONG_DAN_TEST_THU_CONG.md §2.
A36: Lưu ý email | B36: Các địa chỉ *@gmail.com trên là của người khác. Trước khi test email (PH7), đổi email tài khoản test sang email của bạn.
A38: Hiện trạng môi trường (17/10/2026)
A39: Đang chạy | B39: Hạ tầng Docker, 8 service Java, Gateway, AI search (8001), FE. Đã nạp 1.123 sản phẩm, tồn kho 10/phiên bản, chỉ mục tìm kiếm.
A40: Chưa chạy | B40: chatbot (8002), recs (8003), forecast (8004). Các ca cần những service này ghi 'Bị chặn' cho đến khi bật.
A41: Chưa có dữ liệu | B41: Dữ liệu tổng hợp user/đơn/hành vi (tools/data-seed). Nhóm PH9 cần dữ liệu này.
A43: Quy tắc an toàn
A44: Kafka | B44: Không gửi message tay vào các topic dùng chung (order-events, payment-events…). Chỉ tạo dữ liệu qua giao diện/API; các lệnh Kafka trong file này chỉ đọc.
A45: Docker | B45: Không dùng `docker compose down -v` (xóa toàn bộ dữ liệu).
A46: Dọn dữ liệu | B46: Sau khi test: hủy đơn test chưa giao, nhập lại kho, tắt/xóa chiến dịch test, xóa tài khoản test tự đăng ký.
...

Sheet Test case
A1: ID | B1: Phân hệ | C1: Chức năng | D1: Tiêu đề test case | E1: Loại | F1: Ưu tiên | G1: Tài khoản | H1: Tiền điều kiện | I1: Các bước thực hiện | J1: Dữ liệu test | K1: Kết quả mong đợi | L1: Cách kiểm chứng | M1: Kết quả thực tế | N1: Trạng thái | O1: Người test | P1: Ngày test | Q1: Mã lỗi / Ghi chú
A2: SYS-01 | B2: SYS – Hạ tầng & khởi động | C2: Docker | D2: Các container hạ tầng đang chạy | E2: Chức năng | F2: Cao | G2: — | H2: Docker Desktop đang chạy. | I2: 1. Chạy `docker ps -a`. | K2: infra-mariadb, mongodb, redis, kafka, debezium-connect, elasticsearch, minio, keycloak, eureka, gateway đều Up. `infra-debezium-init` Exited (0) là bình thường. | L2: Cột STATUS của `docker ps -a`. | N2: Chưa test
A3: SYS-02 | B3: SYS – Hạ tầng & khởi động | C3: Eureka | D3: Đủ 9 service đăng ký Eureka | E3: Chức năng | F3: Cao | G3: — | H3: Đã chạy 8 service Java. | I3: 1. Mở http://localhost:8761. | K3: API-GATEWAY, USER, PRODUCT, ORDER, INVENTORY, PAYMENT, PROMOTION, NOTIFICATION, CHAT-SERVICE đều UP. | L3: Bảng 'Instances currently registered'. | N3: Chưa test
A4: SYS-03 | B4: SYS – Hạ tầng & khởi động | C4: Gateway | D4: Gateway định tuyến tới product-service | E4: Tích hợp | F4: Cao | G4: — | H4: SYS-02 đạt. | I4: 1. Mở http://localhost:8080/api/v1/public/products?page=0&size=1. | K4: HTTP 200, `code` = SUCCESS, có 1 sản phẩm. | L4: Nội dung JSON trả về. | N4: Chưa test
A5: SYS-04 | B5: SYS – Hạ tầng & khởi động | C5: Debezium | D5: Hai connector outbox đang chạy | E5: Tích hợp | F5: Cao | G5: — | H5: Order/payment-service đã khởi động ít nhất 1 lần. | I5: 1. Mở http://localhost:8088/connectors/order-outbox-connector/status. 2. Mở .../payment-outbox-connector/status. | K5: Cả connector và task đều RUNNING. | L5: Trường `connector.state`, `tasks[].state`. | N5: Chưa test
A6: SYS-05 | B6: SYS – Hạ tầng & khởi động | C6: Keycloak | D6: Realm ecommerce-realm sẵn sàng | E6: Chức năng | F6: Cao | G6: — | I6: 1. Mở http://localhost:8083/realms/ecommerce-realm. | K6: HTTP 200, có `public_key`. | L6: JSON trả về. | N6: Chưa test
A7: SYS-06 | B7: SYS – Hạ tầng & khởi động | C7: AI | D7: Health của các service AI | E7: Chức năng | F7: Trung bình | G7: — | H7: Đã bật service AI tương ứng (8002/8003/8004). | I7: 1. Mở lần lượt http://localhost:8001/health, 8002/health, 8003/health, 8004/health. | K7: Mỗi service trả HTTP 200, `status` = UP. | L7: JSON trả về. | N7: Chưa test
A8: SYS-07 | B8: SYS – Hạ tầng & khởi động | C8: Frontend | D8: FE tải được trang chủ | E8: Chức năng | F8: Cao | G8: Khách (chưa đăng nhập) | H8: `npm run dev` trong FE. | I8: 1. Mở http://localhost:5173. 2. Mở F12 → Console. | K8: Trang chủ hiển thị, Console không có lỗi đỏ. | L8: F12 → Console. | N8: Chưa test
A9: SYS-08 | B9: SYS – Hạ tầng & khởi động | C9: Elasticsearch | D9: Chỉ mục sản phẩm có dữ liệu | E9: Tích hợp | F9: Trung bình | G9: — | H9: Đã nạp catalog. | I9: 1. Mở http://localhost:9200/products/_count. | K9: `count` bằng số sản phẩm đang có (≈1.123 sau khi nạp catalog). | L9: JSON trả về. | N9: Chưa test
A10: SYS-09 | B10: SYS – Hạ tầng & khởi động | C10: MinIO | D10: MinIO có bucket ảnh | E10: Tích hợp | F10: Thấp | G10: — | I10: 1. Mở http://localhost:9001, đăng nhập bằng thông tin MinIO trong `BE/docker-compose-infra.yml`. | K10: Thấy bucket ảnh sản phẩm và bucket `chat-images` (bucket chat được tạo khi gửi ảnh đầu tiên). | L10: Giao diện MinIO. | N10: Chưa test
A11: PH1-01 | B11: PH1 – Tài khoản & phân quyền | C11: Đăng ký | D11: Đăng ký tài khoản mới | E11: Chức năng | F11: Cao | G11: Khách (chưa đăng nhập) | H11: Email chưa dùng. | I11: 1. Vào http://localhost:5173/register. 2. Điền họ tên, email, mật khẩu. 3. Gửi. | J11: Email của bạn | K11: Chuyển sang trang Keycloak (giao diện techstore), tạo xong quay về trang chủ ở trạng thái đã đăng nhập. | L11: Keycloak → ecommerce-realm → Users có user mới, role ROLE_CUSTOMER. | N11: Chưa test
A12: PH1-02 | B12: PH1 – Tài khoản & phân quyền | C12: Đăng ký | D12: Đăng ký với email đã tồn tại | E12: Ngoại lệ | F12: Trung bình | G12: Khách (chưa đăng nhập) | H12: Email đã có trong realm. | I12: 1. Đăng ký lại bằng email ở PH1-01. | K12: Keycloak báo email đã tồn tại, không tạo user mới. | L12: Keycloak → Users. | N12: Chưa test
A13: PH1-03 | B13: PH1 – Tài khoản & phân quyền | C13: Hồ sơ | D13: Tự tạo hồ sơ ở lần truy cập đầu | E13: Tích hợp | F13: Cao | G13: Tài khoản vừa đăng ký | H13: PH1-01 đạt. | I13: 1. Mở /profile lần đầu. | K13: Trang hồ sơ hiển thị, user-service tự tạo hồ sơ và phát `user-created-events`. | L13: MariaDB `ecommerce_user_db.users` có dòng mới với keycloak_user_id của tài khoản. | N13: Chưa test
A14: PH1-04 | B14: PH1 – Tài khoản & phân quyền | C14: Đăng nhập | D14: Đăng nhập đúng mật khẩu | E14: Chức năng | F14: Cao | G14: customer | H14: Đã đặt mật khẩu cho customer. | I14: 1. Vào /login. 2. Nhập username và mật khẩu. | K14: Đăng nhập thành công, header hiện tên tài khoản. | L14: Giao diện header. | N14: Chưa test
A15: PH1-05 | B15: PH1 – Tài khoản & phân quyền | C15: Đăng nhập | D15: Đăng nhập sai mật khẩu | E15: Ngoại lệ | F15: Cao | G15: customer | I15: 1. Vào /login. 2. Nhập sai mật khẩu. | J15: Mật khẩu sai bất kỳ | K15: Keycloak báo sai thông tin đăng nhập, không vào được. | L15: Giao diện Keycloak. | N15: Chưa test
A16: PH1-06 | B16: PH1 – Tài khoản & phân quyền | C16: Đăng nhập | D16: Đăng nhập bằng Google | E16: Tích hợp | F16: Thấp | G16: Khách (chưa đăng nhập) | H16: Có GOOGLE_CLIENT_ID trong BE/.env. | I16: 1. Trang đăng nhập Keycloak → bấm Google. 2. Chọn tài khoản Google. | K16: Đăng nhập thành công, quay về web. | L16: Keycloak → Users có user liên kết Google. | N16: Chưa test
A17: PH1-07 | B17: PH1 – Tài khoản & phân quyền | C17: Hồ sơ | D17: Sửa họ tên, SĐT, ảnh đại diện | E17: Chức năng | F17: Trung bình | G17: customer | I17: 1. /profile?tab=account. 2. Sửa họ tên, SĐT, tải ảnh. 3. Lưu, rồi F5. | J17: Ảnh JPG < 2MB | K17: Lưu thành công, tải lại vẫn giữ thông tin mới. | L17: Ảnh có trong MinIO. | N17: Chưa test
A18: PH1-08 | B18: PH1 – Tài khoản & phân quyền | C18: Địa chỉ | D18: Thêm, sửa, xóa địa chỉ | E18: Chức năng | F18: Cao | G18: customer | I18: 1. /profile?tab=addresses → Thêm. 2. Chọn tỉnh → phường/xã, nhập chi tiết. 3. Sửa địa chỉ vừa thêm. 4. Xóa. | K18: Thêm/sửa/xóa thành công; danh sách phường/xã đổi theo tỉnh. | L18: Danh sách địa chỉ. | N18: Chưa test
A19: PH1-09 | B19: PH1 – Tài khoản & phân quyền | C19: Địa chỉ | D19: Chỉ một địa chỉ mặc định | E19: Chức năng | F19: Trung bình | G19: customer | H19: Có ≥ 2 địa chỉ. | I19: 1. Đặt địa chỉ B làm mặc định. | K19: B là mặc định, địa chỉ mặc định cũ mất cờ mặc định. | L19: Danh sách địa chỉ. | N19: Chưa test
A20: PH1-10 | B20: PH1 – Tài khoản & phân quyền | C20: Hạng thành viên | D20: Xem hạng và điểm | E20: Chức năng | F20: Trung bình | G20: customer | I20: 1. /profile?tab=membership. | K20: Hiện hạng (MEMBER/SILVER/GOLD/VIP) và số điểm hiện có. | L20: Giao diện. | N20: Chưa test
A21: PH1-11 | B21: PH1 – Tài khoản & phân quyền | C21: Phân quyền | D21: Chưa đăng nhập vào trang cần đăng nhập | E21: Phân quyền | F21: Cao | G21: Khách (chưa đăng nhập) | H21: Đã đăng xuất. | I21: 1. Mở /cart. | K21: Bị chuyển sang đăng nhập. | L21: URL trình duyệt. | N21: Chưa test
A22: PH1-12 | B22: PH1 – Tài khoản & phân quyền | C22: Phân quyền | D22: Customer vào trang quản trị | E22: Phân quyền | F22: Cao | G22: customer | I22: 1. Mở /admin. | K22: Bị đẩy về trang chủ. | L22: URL trình duyệt. | N22: Chưa test
A23: PH1-13 | B23: PH1 – Tài khoản & phân quyền | C23: Phân quyền | D23: Staff vào trang quản trị | E23: Phân quyền | F23: Cao | G23: staff | I23: 1. Mở /admin. | K23: Vào được, thấy đủ các tab. | L23: Giao diện. | N23: Chưa test
A24: PH1-14 | B24: PH1 – Tài khoản & phân quyền | C24: Phân quyền | D24: Staff không được đổi vai trò / khóa user | E24: Phân quyền | F24: Cao | G24: staff | I24: 1. Tab Customers → đổi vai trò hoặc khóa một user. | K24: Thao tác bị từ chối (HTTP 403). | L24: F12 → Network. | N24: Chưa test
A25: PH1-15 | B25: PH1 – Tài khoản & phân quyền | C25: Quản trị khách hàng | D25: Admin đổi hạng khách hàng | E25: Chức năng | F25: Trung bình | G25: admin | I25: 1. Tab Customers → đổi hạng một user test từ MEMBER sang GOLD. 2. Đăng nhập user đó, xem tab membership. | K25: Hạng mới hiển thị đúng. | L25: Giao diện 2 phía. | N25: Chưa test
A26: PH1-16 | B26: PH1 – Tài khoản & phân quyền | C26: Quản trị khách hàng | D26: Admin khóa (blacklist) khách hàng | E26: Chức năng | F26: Trung bình | G26: admin | I26: 1. Tab Customers → khóa một user test. | K26: Trạng thái khóa được lưu và hiển thị trong danh sách. | L26: Danh sách khách; cột is_blacklisted trong DB. | N26: Chưa test
A27: PH1-17 | B27: PH1 – Tài khoản & phân quyền | C27: Quản trị khách hàng | D27: Admin đặt lại mật khẩu khách hàng | E27: Chức năng | F27: Trung bình | G27: admin | I27: 1. Tab Customers → reset mật khẩu một user test. 2. Đăng nhập bằng mật khẩu mới. | K27: Đăng nhập được bằng mật khẩu mới. | L27: Đăng nhập thử. | N27: Chưa test
A28: PH1-18 | B28: PH1 – Tài khoản & phân quyền | C28: Quản trị khách hàng | D28: Admin gán vai trò STAFF | E28: Phân quyền | F28: Trung bình | G28: admin | I28: 1. Gán vai trò STAFF cho user test. 2. User đó đăng xuất, đăng nhập lại, mở /admin. | K28: User vào được /admin. | L28: Giao diện. | N28: Chưa test
A29: PH1-19 | B29: PH1 – Tài khoản & phân quyền | C29: Phiên đăng nhập | D29: Token hết hạn khi đang dùng | E29: Ngoại lệ | F29: Thấp | G29: customer | I29: 1. Đăng nhập, để tab mở > 15 phút. 2. Thao tác một trang cần đăng nhập. | K29: FE tự làm mới token hoặc yêu cầu đăng nhập lại; không lỗi trắng trang. | L29: Giao diện, F12 → Network. | N29: Chưa test
A30: PH2-01 | B30: PH2 – Sản phẩm & tìm kiếm | C30: Trang chủ | D30: Trang chủ cho khách | E30: Chức năng | F30: Cao | G30: Khách (chưa đăng nhập) | H30: Đã nạp catalog. | I30: 1. Mở /. | K30: Có flash deal, danh mục, thương hiệu, khối gợi ý 3 tab. | L30: Giao diện. | N30: Chưa test
A31: PH2-02 | B31: PH2 – Sản phẩm & tìm kiếm | C31: Danh mục | D31: Lọc theo danh mục | E31: Chức năng | F31: Cao | G31: Khách (chưa đăng nhập) | I31: 1. /category → chọn danh mục 'Laptop'. | K31: Chỉ hiện sản phẩm thuộc danh mục đã chọn. | L31: Giao diện. | N31: Chưa test
A32: PH2-03 | B32: PH2 – Sản phẩm & tìm kiếm | C32: Danh mục | D32: Lọc theo khoảng giá | E32: Chức năng | F32: Trung bình | G32: Khách (chưa đăng nhập) | I32: 1. /category → đặt khoảng giá. | J32: 5.000.000 – 10.000.000đ | K32: Mọi sản phẩm nằm trong khoảng giá. | L32: Giao diện. | N32: Chưa test
A33: PH2-04 | B33: PH2 – Sản phẩm & tìm kiếm | C33: Danh mục | D33: Lọc theo thương hiệu | E33: Chức năng | F33: Trung bình | G33: Khách (chưa đăng nhập) | I33: 1. /category → chọn thương hiệu. | J33: Samsung | K33: Chỉ hiện sản phẩm của thương hiệu đã chọn. | L33: Giao diện. | N33: Chưa test
A34: PH2-05 | B34: PH2 – Sản phẩm & tìm kiếm | C34: Danh mục | D34: Sắp xếp theo giá | E34: Chức năng | F34: Trung bình | G34: Khách (chưa đăng nhập) | I34: 1. Đổi sắp xếp giá tăng dần, rồi giảm dần. | K34: Thứ tự đúng theo giá. | L34: Giao diện. | N34: Chưa test
A35: PH2-06 | B35: PH2 – Sản phẩm & tìm kiếm | C35: Danh mục | D35: Phân trang | E35: Chức năng | F35: Thấp | G35: Khách (chưa đăng nhập) | I35: 1. Sang trang 2, 3. | K35: Danh sách đổi, không trùng sản phẩm giữa các trang. | L35: Giao diện. | N35: Chưa test
A36: PH2-07 | B36: PH2 – Sản phẩm & tìm kiếm | C36: Chi tiết | D36: Xem chi tiết khi chưa đăng nhập | E36: Chức năng | F36: Cao | G36: Khách (chưa đăng nhập) | I36: 1. Mở /product/1. | K36: Trang hiện đủ thông tin, tên người đánh giá hiển thị. | L36: Giao diện. | N36: Chưa test
A37: PH2-08 | B37: PH2 – Sản phẩm & tìm kiếm | C37: Chi tiết | D37: Chọn phiên bản sản phẩm | E37: Chức năng | F37: Cao | G37: Khách (chưa đăng nhập) | H37: Sản phẩm có ≥ 2 phiên bản. | I37: 1. Chọn màu/dung lượng khác. | K37: Giá và tồn kho đổi theo phiên bản. | L37: Giao diện. | N37: Chưa test
A38: PH2-09 | B38: PH2 – Sản phẩm & tìm kiếm | C38: Chi tiết | D38: Ảnh và các tab thông tin | E38: Chức năng | F38: Thấp | G38: Khách (chưa đăng nhập) | I38: 1. Phóng to ảnh. 2. Mở tab thông số, bảo hành, đánh giá. | K38: Ảnh phóng to được; các tab hiển thị nội dung. | L38: Giao diện. | N38: Chưa test
A39: PH2-10 | B39: PH2 – Sản phẩm & tìm kiếm | C39: Chi tiết | D39: Thêm vào giỏ khi chưa đăng nhập | E39: Phân quyền | F39: Cao | G39: Khách (chưa đăng nhập) | I39: 1. Bấm Thêm vào giỏ. | K39: Yêu cầu đăng nhập. | L39: Giao diện. | N39: Chưa test
A40: PH2-11 | B40: PH2 – Sản phẩm & tìm kiếm | C40: Tìm kiếm | D40: Tìm theo từ khóa trên header | E40: Chức năng | F40: Cao | G40: Khách (chưa đăng nhập) | I40: 1. Gõ 'iphone' vào ô tìm kiếm, Enter. | J40: iphone | K40: Trang /search?q=iphone có kết quả là iPhone. | L40: Giao diện. | N40: Chưa test
...

Sheet Tổng hợp
A1: TỔNG HỢP KẾT QUẢ TEST
A2: Tự cập nhật theo cột Trạng thái ở sheet 'Test case'. Tỷ lệ đạt = Đạt / (Đạt + Không đạt + Bị chặn).
A4: Phân hệ | B4: Tổng | C4: Đạt | D4: Không đạt | E4: Bị chặn | F4: Bỏ qua | G4: Chưa test | H4: % đã test | I4: % đạt
A5: SYS – Hạ tầng & khởi động | B5: =COUNTIFS('Test case'!$B$2:$B$187,$A5) -> 9 | C5: =COUNTIFS('Test case'!$B$2:$B$187,$A5,'Test case'!$N$2:$N$187,"Đạt") -> 0 | D5: =COUNTIFS('Test case'!$B$2:$B$187,$A5,'Test case'!$N$2:$N$187,"Không đạt") -> 0 | E5: =COUNTIFS('Test case'!$B$2:$B$187,$A5,'Test case'!$N$2:$N$187,"Bị chặn") -> 0 | F5: =COUNTIFS('Test case'!$B$2:$B$187,$A5,'Test case'!$N$2:$N$187,"Bỏ qua") -> 0 | G5: =COUNTIFS('Test case'!$B$2:$B$187,$A5,'Test case'!$N$2:$N$187,"Chưa test") -> 9 | H5: =IFERROR((B5-G5)/B5,0) -> 0 | I5: =IFERROR(C5/(C5+D5+E5),0) -> 0
A6: PH1 – Tài khoản & phân quyền | B6: =COUNTIFS('Test case'!$B$2:$B$187,$A6) -> 19 | C6: =COUNTIFS('Test case'!$B$2:$B$187,$A6,'Test case'!$N$2:$N$187,"Đạt") -> 0 | D6: =COUNTIFS('Test case'!$B$2:$B$187,$A6,'Test case'!$N$2:$N$187,"Không đạt") -> 0 | E6: =COUNTIFS('Test case'!$B$2:$B$187,$A6,'Test case'!$N$2:$N$187,"Bị chặn") -> 0 | F6: =COUNTIFS('Test case'!$B$2:$B$187,$A6,'Test case'!$N$2:$N$187,"Bỏ qua") -> 0 | G6: =COUNTIFS('Test case'!$B$2:$B$187,$A6,'Test case'!$N$2:$N$187,"Chưa test") -> 19 | H6: =IFERROR((B6-G6)/B6,0) -> 0 | I6: =IFERROR(C6/(C6+D6+E6),0) -> 0
A7: PH2 – Sản phẩm & tìm kiếm | B7: =COUNTIFS('Test case'!$B$2:$B$187,$A7) -> 31 | C7: =COUNTIFS('Test case'!$B$2:$B$187,$A7,'Test case'!$N$2:$N$187,"Đạt") -> 0 | D7: =COUNTIFS('Test case'!$B$2:$B$187,$A7,'Test case'!$N$2:$N$187,"Không đạt") -> 0 | E7: =COUNTIFS('Test case'!$B$2:$B$187,$A7,'Test case'!$N$2:$N$187,"Bị chặn") -> 0 | F7: =COUNTIFS('Test case'!$B$2:$B$187,$A7,'Test case'!$N$2:$N$187,"Bỏ qua") -> 0 | G7: =COUNTIFS('Test case'!$B$2:$B$187,$A7,'Test case'!$N$2:$N$187,"Chưa test") -> 31 | H7: =IFERROR((B7-G7)/B7,0) -> 0 | I7: =IFERROR(C7/(C7+D7+E7),0) -> 0
A8: PH3 – Giỏ hàng & đơn hàng | B8: =COUNTIFS('Test case'!$B$2:$B$187,$A8) -> 22 | C8: =COUNTIFS('Test case'!$B$2:$B$187,$A8,'Test case'!$N$2:$N$187,"Đạt") -> 0 | D8: =COUNTIFS('Test case'!$B$2:$B$187,$A8,'Test case'!$N$2:$N$187,"Không đạt") -> 0 | E8: =COUNTIFS('Test case'!$B$2:$B$187,$A8,'Test case'!$N$2:$N$187,"Bị chặn") -> 0 | F8: =COUNTIFS('Test case'!$B$2:$B$187,$A8,'Test case'!$N$2:$N$187,"Bỏ qua") -> 0 | G8: =COUNTIFS('Test case'!$B$2:$B$187,$A8,'Test case'!$N$2:$N$187,"Chưa test") -> 22 | H8: =IFERROR((B8-G8)/B8,0) -> 0 | I8: =IFERROR(C8/(C8+D8+E8),0) -> 0
A9: PH4 – Tồn kho | B9: =COUNTIFS('Test case'!$B$2:$B$187,$A9) -> 6 | C9: =COUNTIFS('Test case'!$B$2:$B$187,$A9,'Test case'!$N$2:$N$187,"Đạt") -> 0 | D9: =COUNTIFS('Test case'!$B$2:$B$187,$A9,'Test case'!$N$2:$N$187,"Không đạt") -> 0 | E9: =COUNTIFS('Test case'!$B$2:$B$187,$A9,'Test case'!$N$2:$N$187,"Bị chặn") -> 0 | F9: =COUNTIFS('Test case'!$B$2:$B$187,$A9,'Test case'!$N$2:$N$187,"Bỏ qua") -> 0 | G9: =COUNTIFS('Test case'!$B$2:$B$187,$A9,'Test case'!$N$2:$N$187,"Chưa test") -> 6 | H9: =IFERROR((B9-G9)/B9,0) -> 0 | I9: =IFERROR(C9/(C9+D9+E9),0) -> 0
A10: PH5 – Thanh toán | B10: =COUNTIFS('Test case'!$B$2:$B$187,$A10) -> 11 | C10: =COUNTIFS('Test case'!$B$2:$B$187,$A10,'Test case'!$N$2:$N$187,"Đạt") -> 0 | D10: =COUNTIFS('Test case'!$B$2:$B$187,$A10,'Test case'!$N$2:$N$187,"Không đạt") -> 0 | E10: =COUNTIFS('Test case'!$B$2:$B$187,$A10,'Test case'!$N$2:$N$187,"Bị chặn") -> 0 | F10: =COUNTIFS('Test case'!$B$2:$B$187,$A10,'Test case'!$N$2:$N$187,"Bỏ qua") -> 0 | G10: =COUNTIFS('Test case'!$B$2:$B$187,$A10,'Test case'!$N$2:$N$187,"Chưa test") -> 11 | H10: =IFERROR((B10-G10)/B10,0) -> 0 | I10: =IFERROR(C10/(C10+D10+E10),0) -> 0
A11: PH6 – Khuyến mãi & chiến dịch | B11: =COUNTIFS('Test case'!$B$2:$B$187,$A11) -> 24 | C11: =COUNTIFS('Test case'!$B$2:$B$187,$A11,'Test case'!$N$2:$N$187,"Đạt") -> 0 | D11: =COUNTIFS('Test case'!$B$2:$B$187,$A11,'Test case'!$N$2:$N$187,"Không đạt") -> 0 | E11: =COUNTIFS('Test case'!$B$2:$B$187,$A11,'Test case'!$N$2:$N$187,"Bị chặn") -> 0 | F11: =COUNTIFS('Test case'!$B$2:$B$187,$A11,'Test case'!$N$2:$N$187,"Bỏ qua") -> 0 | G11: =COUNTIFS('Test case'!$B$2:$B$187,$A11,'Test case'!$N$2:$N$187,"Chưa test") -> 24 | H11: =IFERROR((B11-G11)/B11,0) -> 0 | I11: =IFERROR(C11/(C11+D11+E11),0) -> 0
A12: PH7 – Thông báo email | B12: =COUNTIFS('Test case'!$B$2:$B$187,$A12) -> 6 | C12: =COUNTIFS('Test case'!$B$2:$B$187,$A12,'Test case'!$N$2:$N$187,"Đạt") -> 0 | D12: =COUNTIFS('Test case'!$B$2:$B$187,$A12,'Test case'!$N$2:$N$187,"Không đạt") -> 0 | E12: =COUNTIFS('Test case'!$B$2:$B$187,$A12,'Test case'!$N$2:$N$187,"Bị chặn") -> 0 | F12: =COUNTIFS('Test case'!$B$2:$B$187,$A12,'Test case'!$N$2:$N$187,"Bỏ qua") -> 0 | G12: =COUNTIFS('Test case'!$B$2:$B$187,$A12,'Test case'!$N$2:$N$187,"Chưa test") -> 6 | H12: =IFERROR((B12-G12)/B12,0) -> 0 | I12: =IFERROR(C12/(C12+D12+E12),0) -> 0
A13: PH8 – Hành vi & gợi ý | B13: =COUNTIFS('Test case'!$B$2:$B$187,$A13) -> 13 | C13: =COUNTIFS('Test case'!$B$2:$B$187,$A13,'Test case'!$N$2:$N$187,"Đạt") -> 0 | D13: =COUNTIFS('Test case'!$B$2:$B$187,$A13,'Test case'!$N$2:$N$187,"Không đạt") -> 0 | E13: =COUNTIFS('Test case'!$B$2:$B$187,$A13,'Test case'!$N$2:$N$187,"Bị chặn") -> 0 | F13: =COUNTIFS('Test case'!$B$2:$B$187,$A13,'Test case'!$N$2:$N$187,"Bỏ qua") -> 0 | G13: =COUNTIFS('Test case'!$B$2:$B$187,$A13,'Test case'!$N$2:$N$187,"Chưa test") -> 13 | H13: =IFERROR((B13-G13)/B13,0) -> 0 | I13: =IFERROR(C13/(C13+D13+E13),0) -> 0
A14: PH9 – Phân tích AI & churn | B14: =COUNTIFS('Test case'!$B$2:$B$187,$A14) -> 9 | C14: =COUNTIFS('Test case'!$B$2:$B$187,$A14,'Test case'!$N$2:$N$187,"Đạt") -> 0 | D14: =COUNTIFS('Test case'!$B$2:$B$187,$A14,'Test case'!$N$2:$N$187,"Không đạt") -> 0 | E14: =COUNTIFS('Test case'!$B$2:$B$187,$A14,'Test case'!$N$2:$N$187,"Bị chặn") -> 0 | F14: =COUNTIFS('Test case'!$B$2:$B$187,$A14,'Test case'!$N$2:$N$187,"Bỏ qua") -> 0 | G14: =COUNTIFS('Test case'!$B$2:$B$187,$A14,'Test case'!$N$2:$N$187,"Chưa test") -> 9 | H14: =IFERROR((B14-G14)/B14,0) -> 0 | I14: =IFERROR(C14/(C14+D14+E14),0) -> 0
A15: PH10 – Chatbot & hỗ trợ | B15: =COUNTIFS('Test case'!$B$2:$B$187,$A15) -> 15 | C15: =COUNTIFS('Test case'!$B$2:$B$187,$A15,'Test case'!$N$2:$N$187,"Đạt") -> 0 | D15: =COUNTIFS('Test case'!$B$2:$B$187,$A15,'Test case'!$N$2:$N$187,"Không đạt") -> 0 | E15: =COUNTIFS('Test case'!$B$2:$B$187,$A15,'Test case'!$N$2:$N$187,"Bị chặn") -> 0 | F15: =COUNTIFS('Test case'!$B$2:$B$187,$A15,'Test case'!$N$2:$N$187,"Bỏ qua") -> 0 | G15: =COUNTIFS('Test case'!$B$2:$B$187,$A15,'Test case'!$N$2:$N$187,"Chưa test") -> 15 | H15: =IFERROR((B15-G15)/B15,0) -> 0 | I15: =IFERROR(C15/(C15+D15+E15),0) -> 0
A16: SEC – Bảo mật | B16: =COUNTIFS('Test case'!$B$2:$B$187,$A16) -> 12 | C16: =COUNTIFS('Test case'!$B$2:$B$187,$A16,'Test case'!$N$2:$N$187,"Đạt") -> 0 | D16: =COUNTIFS('Test case'!$B$2:$B$187,$A16,'Test case'!$N$2:$N$187,"Không đạt") -> 0 | E16: =COUNTIFS('Test case'!$B$2:$B$187,$A16,'Test case'!$N$2:$N$187,"Bị chặn") -> 0 | F16: =COUNTIFS('Test case'!$B$2:$B$187,$A16,'Test case'!$N$2:$N$187,"Bỏ qua") -> 0 | G16: =COUNTIFS('Test case'!$B$2:$B$187,$A16,'Test case'!$N$2:$N$187,"Chưa test") -> 12 | H16: =IFERROR((B16-G16)/B16,0) -> 0 | I16: =IFERROR(C16/(C16+D16+E16),0) -> 0
... A18: E2E – Luồng xuyên suốt | B18: =COUNTIFS('Test case'!$B$2:$B$187,$A18) -> 3 | C18: =COUNTIFS('Test case'!$B$2:$B$187,$A18,'Test case'!$N$2:$N$187,"Đạt") -> 0 | D18: =COUNTIFS('Test case'!$B$2:$B$187,$A18,'Test case'!$N$2:$N$187,"Không đạt") -> 0 | E18: =COUNTIFS('Test case'!$B$2:$B$187,$A18,'Test case'!$N$2:$N$187,"Bị chặn") -> 0 | F18: =COUNTIFS('Test case'!$B$2:$B$187,$A18,'Test case'!$N$2:$N$187,"Bỏ qua") -> 0 | G18: =COUNTIFS('Test case'!$B$2:$B$187,$A18,'Test case'!$N$2:$N$187,"Chưa test") -> 3 | H18: =IFERROR((B18-G18)/B18,0) -> 0 | I18: =IFERROR(C18/(C18+D18+E18),0) -> 0
A19: TỔNG CỘNG | B19: =SUM(B5:B18) -> 186 | C19: =SUM(C5:C18) -> 0 | D19: =SUM(D5:D18) -> 0 | E19: =SUM(E5:E18) -> 0 | F19: =SUM(F5:F18) -> 0 | G19: =SUM(G5:G18) -> 186 | H19: =IFERROR((B19-G19)/B19,0) -> 0 | I19: =IFERROR(C19/(C19+D19+E19),0) -> 0
A20: Kiểm tra | B20: =IF(B19=COUNTA('Test case'!$A$2:$A$187),"Khớp tổng số test case","Lệch: kiểm tra cột Phân hệ") -> Khớp tổng số test case
A22: Theo mức ưu tiên
A23: Ưu tiên | B23: Tổng | C23: Đạt | D23: Không đạt | E23: Bị chặn | F23: Bỏ qua | G23: Chưa test
A24: Cao | B24: =COUNTIFS('Test case'!$F$2:$F$187,$A24) -> 70 | C24: =COUNTIFS('Test case'!$F$2:$F$187,$A24,'Test case'!$N$2:$N$187,"Đạt") -> 0 | D24: =COUNTIFS('Test case'!$F$2:$F$187,$A24,'Test case'!$N$2:$N$187,"Không đạt") -> 0 | E24: =COUNTIFS('Test case'!$F$2:$F$187,$A24,'Test case'!$N$2:$N$187,"Bị chặn") -> 0 | F24: =COUNTIFS('Test case'!$F$2:$F$187,$A24,'Test case'!$N$2:$N$187,"Bỏ qua") -> 0 | G24: =COUNTIFS('Test case'!$F$2:$F$187,$A24,'Test case'!$N$2:$N$187,"Chưa test") -> 70
A25: Trung bình | B25: =COUNTIFS('Test case'!$F$2:$F$187,$A25) -> 75 | C25: =COUNTIFS('Test case'!$F$2:$F$187,$A25,'Test case'!$N$2:$N$187,"Đạt") -> 0 | D25: =COUNTIFS('Test case'!$F$2:$F$187,$A25,'Test case'!$N$2:$N$187,"Không đạt") -> 0 | E25: =COUNTIFS('Test case'!$F$2:$F$187,$A25,'Test case'!$N$2:$N$187,"Bị chặn") -> 0 | F25: =COUNTIFS('Test case'!$F$2:$F$187,$A25,'Test case'!$N$2:$N$187,"Bỏ qua") -> 0 | G25: =COUNTIFS('Test case'!$F$2:$F$187,$A25,'Test case'!$N$2:$N$187,"Chưa test") -> 75
A26: Thấp | B26: =COUNTIFS('Test case'!$F$2:$F$187,$A26) -> 41 | C26: =COUNTIFS('Test case'!$F$2:$F$187,$A26,'Test case'!$N$2:$N$187,"Đạt") -> 0 | D26: =COUNTIFS('Test case'!$F$2:$F$187,$A26,'Test case'!$N$2:$N$187,"Không đạt") -> 0 | E26: =COUNTIFS('Test case'!$F$2:$F$187,$A26,'Test case'!$N$2:$N$187,"Bị chặn") -> 0 | F26: =COUNTIFS('Test case'!$F$2:$F$187,$A26,'Test case'!$N$2:$N$187,"Bỏ qua") -> 0 | G26: =COUNTIFS('Test case'!$F$2:$F$187,$A26,'Test case'!$N$2:$N$187,"Chưa test") -> 41

Sheet Hành vi đã biết
A1: HÀNH VI ĐÃ BIẾT – KHÔNG GHI LÀ LỖI MỚI
A2: Nguồn: docs/test/HUONG_DAN_TEST_THU_CONG.md §13 và rà soát code nhánh develop (10/2026).
A4: Chức năng | B4: Hành vi hiện tại
A5: Tìm kiếm trên web | B5: Ô tìm kiếm gọi product-service (Elasticsearch, so khớp chứa chuỗi), chưa dùng tìm kiếm ngữ nghĩa; tìm kiếm ngữ nghĩa chỉ thử được qua Swagger 8001.
A6: Tìm kiếm bằng ảnh | B6: Nhãn 'YOLO v8 detected' luôn hiện; 'Độ khớp %' không phản ánh độ tin cậy; tiêu đề hiện Kết quả cho "".
A7: Sản phẩm liên quan | B7: Luôn là 8 sản phẩm đầu danh sách, không phải AI.
A8: Điểm đánh giá | B8: Trang sản phẩm hiện 0 sao dù có đánh giá.
A9: /stores, /tradein | B9: Chưa có backend.
A10: Vận chuyển | B10: Mã vận đơn giả MOCK-GHTK-*, phí cố định 30.000đ.
A11: Hủy đơn | B11: Giới hạn 2 giờ chỉ kiểm tra ở FE; API không kiểm tra thời gian. Không có chọn lý do hủy.
A12: Điểm thưởng | B12: Không tự cộng cho mọi đơn, chỉ cộng qua chiến dịch.
A13: Chiến dịch hẹn giờ | B13: Hành động cần người dùng bị bỏ qua; xóa chiến dịch không gỡ deployment Camunda.
A14: Thông báo | B14: Không có thông báo đẩy (FCM chỉ lưu token); chuông thông báo admin chỉ trang trí; chưa có email hoàn tiền.
A15: Gợi ý mua kèm (giỏ hàng) | B15: Trả danh sách phổ biến, chưa dựa vào sản phẩm trong giỏ.
... A20: Kiểm tra chiến dịch không hợp lệ | B20: API trả HTTP 200 với code VALIDATION_FAILED, không phải 400.

Sheet Ghi lỗi
A1: Mã lỗi | B1: Test case ID | C1: Phân hệ | D1: Mức độ | E1: Tiêu đề lỗi | F1: Bước tái hiện | G1: Kết quả mong đợi | H1: Kết quả thực tế | I1: Ảnh / log | J1: Người test | K1: Ngày phát hiện | L1: Trạng thái xử lý
A2: BUG-VD | B2: PH3-17 | C2: PH3 – Giỏ hàng & đơn hàng | D2: Cao | E2: (VÍ DỤ – xóa dòng này khi dùng) Đặt vượt tồn kho vẫn tạo đơn | F2: 1. Đăng nhập customer. 2. Đặt 15 sản phẩm khi tồn kho 10. | G2: Bị từ chối, HTTP 400 | H2: Đơn được tạo ở PENDING | I2: screenshot-01.png | J2: Tên bạn | K2: 17/10/2026 | L2: Mới
